Workbook

Sheet Answer
A1: Question 59 -- Durum wheat (Data sheet, cols A:E) and Canola (cols G:K)
A3: Durum -- mean | B3: =AVERAGE('Data'!E2:E39)
A4: Durum -- CV | B4: =_xlfn.STDEV.S('Data'!E2:E39)/AVERAGE('Data'!E2:E39)
A6: Province | B6: Durum rows (non-blank) | C6: Canola rows (non-blank)
A7: Alberta | B7: =COUNTIFS('Data'!B2:B39,A7,'Data'!E2:E39,"<>") | C7: =COUNTIFS('Data'!H2:H76,A7,'Data'!K2:K76,"<>")
A8: British Columbia | B8: =COUNTIFS('Data'!B2:B39,A8,'Data'!E2:E39,"<>") | C8: =COUNTIFS('Data'!H2:H76,A8,'Data'!K2:K76,"<>")
A9: Manitoba | B9: =COUNTIFS('Data'!B2:B39,A9,'Data'!E2:E39,"<>") | C9: =COUNTIFS('Data'!H2:H76,A9,'Data'!K2:K76,"<>")
A10: New Brunswick | B10: =COUNTIFS('Data'!B2:B39,A10,'Data'!E2:E39,"<>") | C10: =COUNTIFS('Data'!H2:H76,A10,'Data'!K2:K76,"<>")
A11: Newfoundland and Labrador | B11: =COUNTIFS('Data'!B2:B39,A11,'Data'!E2:E39,"<>") | C11: =COUNTIFS('Data'!H2:H76,A11,'Data'!K2:K76,"<>")
A12: Nova Scotia | B12: =COUNTIFS('Data'!B2:B39,A12,'Data'!E2:E39,"<>") | C12: =COUNTIFS('Data'!H2:H76,A12,'Data'!K2:K76,"<>")
A13: Ontario | B13: =COUNTIFS('Data'!B2:B39,A13,'Data'!E2:E39,"<>") | C13: =COUNTIFS('Data'!H2:H76,A13,'Data'!K2:K76,"<>")
A14: Prince Edward Island | B14: =COUNTIFS('Data'!B2:B39,A14,'Data'!E2:E39,"<>") | C14: =COUNTIFS('Data'!H2:H76,A14,'Data'!K2:K76,"<>")
A15: Quebec | B15: =COUNTIFS('Data'!B2:B39,A15,'Data'!E2:E39,"<>") | C15: =COUNTIFS('Data'!H2:H76,A15,'Data'!K2:K76,"<>")
A16: Saskatchewan | B16: =COUNTIFS('Data'!B2:B39,A16,'Data'!E2:E39,"<>") | C16: =COUNTIFS('Data'!H2:H76,A16,'Data'!K2:K76,"<>")
A17: Provinces reporting | B17: =COUNTIF(B7:B16,">0") | C17: =COUNTIF(C7:C16,">0")
A19: Five provinces report durum against eight for canola -- the durum average summarises far fewer provinces, so it applies to a narrower part of the country.
A22: The durum figure is still an accurate average of the provinces that report it -- it simply describes fewer provinces than the canola figure, not the whole country.
A25: Durum's CV (about 0.29) is much higher than canola's (about 0.13) -- canola's provincial yields are steadier.
A28: An average over five provinces means something different from one over ten -- the contributor count sets how broadly the number applies.
A31: Part (a)
A32: Part (b)
A33: Part (c)
A34: Part (d)
A35: Part (e)

Sheet Data
A1: Year | B1: Province | C1: Crop | D1: Seeded_acres | E1: Yield_bu_ac | G1: Year | H1: Province | I1: Crop | J1: Seeded_acres | K1: Yield_bu_ac
A2: 2015 | B2: Alberta | C2: Durum wheat | D2: 890000 | E2: 34.5 | G2: 2015 | H2: Alberta | I2: Canola | J2: 6265000 | K2: 41.4
A3: 2015 | B3: Saskatchewan | C3: Durum wheat | D3: 4900000 | E3: 34.6 | G3: 2015 | H3: British Columbia | I3: Canola | J3: 90000 | K3: 34.7
A4: 2016 | B4: Alberta | C4: Durum wheat | D4: 1101500 | E4: 53.6 | G4: 2015 | H4: Manitoba | I4: Canola | J4: 3215000 | K4: 39.5
A5: 2016 | B5: Saskatchewan | C5: Durum wheat | D5: 5000000 | E5: 48.5 | G5: 2015 | H5: Ontario | I5: Canola | J5: 35000 | K5: 42.9
A6: 2017 | B6: Alberta | C6: Durum wheat | D6: 1090000 | E6: 36.7 | G6: 2015 | H6: Quebec | I6: Canola | J6: 29700 | K6: 39.7
A7: 2017 | B7: Saskatchewan | C7: Durum wheat | D7: 4115000 | E7: 35 | G7: 2015 | H7: Saskatchewan | I7: Canola | J7: 11150000 | K7: 37.9
A8: 2018 | B8: Alberta | C8: Durum wheat | D8: 1184800 | E8: 35.6 | G8: 2016 | H8: Alberta | I8: Canola | J8: 6165700 | K8: 45.4
A9: 2018 | B9: British Columbia | C9: Durum wheat | D9: 900 | E9: 33.8 | G9: 2016 | H9: British Columbia | I9: Canola | J9: 95000 | K9: 41.9
A10: 2018 | B10: Saskatchewan | C10: Durum wheat | D10: 4989600 | E10: 34.9 | G10: 2016 | H10: Manitoba | I10: Canola | J10: 3199644 | K10: 37.1
A11: 2019 | B11: Alberta | C11: Durum wheat | D11: 775000 | E11: 32 | G11: 2016 | H11: Ontario | I11: Canola | J11: 39500 | K11: 41.9
A12: 2019 | B12: Manitoba | C12: Durum wheat | D12: 18400 | E12: 54.5 | G12: 2016 | H12: Quebec | I12: Canola | J12: 34200 | K12: 42.1
A13: 2019 | B13: Saskatchewan | C13: Durum wheat | D13: 4100000 | E13: 40.5 | G13: 2016 | H13: Saskatchewan | I13: Canola | J13: 11250000 | K13: 42.1
... A18: 2021 | B18: Manitoba | C18: Durum wheat | D18: 15390 | E18: 40 | G18: 2017 | H18: Quebec | I18: Canola | J18: 37100 | K18: 44.3
A19: 2021 | B19: Ontario | C19: Durum wheat | D19: 3920 | G19: 2017 | H19: Saskatchewan | I19: Canola | J19: 12730000 | K19: 39.3
A20: 2021 | B20: Prince Edward Island | C20: Durum wheat | D20: 183 | G20: 2018 | H20: Alberta | I20: Canola | J20: 6810000 | K20: 38.8
A21: 2021 | B21: Quebec | C21: Durum wheat | D21: 7109 | G21: 2018 | H21: British Columbia | I21: Canola | J21: 137000 | K21: 40.7
A22: 2021 | B22: Saskatchewan | C22: Durum wheat | D22: 4671794 | E22: 19.6 | G22: 2018 | H22: Manitoba | I22: Canola | J22: 3416000 | K22: 43.3
A23: 2022 | B23: Alberta | C23: Durum wheat | D23: 1086800 | E23: 40.9 | G23: 2018 | H23: New Brunswick | I23: Canola | J23: 1000 | K23: 34.5
A24: 2022 | B24: British Columbia | C24: Durum wheat | D24: 4600 | E24: 23.6 | G24: 2018 | H24: Ontario | I24: Canola | J24: 63000 | K24: 47.1
A25: 2022 | B25: Manitoba | C25: Durum wheat | D25: 35100 | E25: 56 | G25: 2018 | H25: Quebec | I25: Canola | J25: 36200 | K25: 43.8
A26: 2022 | B26: Saskatchewan | C26: Durum wheat | D26: 4864700 | E26: 34.6 | G26: 2018 | H26: Saskatchewan | I26: Canola | J26: 12350000 | K26: 40.7
A27: 2023 | B27: Alberta | C27: Durum wheat | D27: 996800 | E27: 29.2 | G27: 2019 | H27: Alberta | I27: Canola | J27: 5933500 | K27: 40.3
A28: 2023 | B28: Manitoba | C28: Durum wheat | D28: 44400 | E28: 49.8 | G28: 2019 | H28: British Columbia | I28: Canola | J28: 85800 | K28: 41.6
A29: 2023 | B29: Quebec | C29: Durum wheat | D29: 9900 | E29: 39.2 | G29: 2019 | H29: Manitoba | I29: Canola | J29: 3307800 | K29: 42
A30: 2023 | B30: Saskatchewan | C30: Durum wheat | D30: 4970700 | E30: 25.6 | G30: 2019 | H30: New Brunswick | I30: Canola | J30: 1400 | K30: 37.3
A31: 2024 | B31: Alberta | C31: Durum wheat | D31: 1189800 | E31: 40.9 | G31: 2019 | H31: Ontario | I31: Canola | J31: 46600 | K31: 43.2
A32: 2024 | B32: British Columbia | C32: Durum wheat | D32: 5900 | E32: 39.7 | G32: 2019 | H32: Prince Edward Island | I32: Canola | J32: 900 | K32: 40.7
A33: 2024 | B33: Manitoba | C33: Durum wheat | D33: 24100 | E33: 54.2 | G33: 2019 | H33: Quebec | I33: Canola | J33: 29900 | K33: 39.5
A34: 2024 | B34: New Brunswick | C34: Durum wheat | D34: 1900 | G34: 2019 | H34: Saskatchewan | I34: Canola | J34: 11775000 | K34: 42.8
A35: 2024 | B35: Saskatchewan | C35: Durum wheat | D35: 5115800 | E35: 35.8 | G35: 2020 | H35: Alberta | I35: Canola | J35: 5876000 | K35: 40.2
A36: 2025 | B36: Alberta | C36: Durum wheat | D36: 1327400 | E36: 44.1 | G36: 2020 | H36: British Columbia | I36: Canola | J36: 92100 | K36: 30
A37: 2025 | B37: British Columbia | C37: Durum wheat | D37: 5300 | E37: 72.6 | G37: 2020 | H37: Manitoba | I37: Canola | J37: 3414100 | K37: 41.4
A38: 2025 | B38: Manitoba | C38: Durum wheat | D38: 56000 | E38: 66.9 | G38: 2020 | H38: New Brunswick | I38: Canola | J38: 1200 | K38: 42.1
A39: 2025 | B39: Saskatchewan | C39: Durum wheat | D39: 5118800 | E39: 39.6 | G39: 2020 | H39: Ontario | I39: Canola | J39: 32400 | K39: 45.9
G40: 2020 | H40: Quebec | I40: Canola | J40: 27600 | K40: 38.6
G41: 2020 | H41: Saskatchewan | I41: Canola | J41: 11339200 | K41: 42.7
G42: 2021 | H42: Alberta | I42: Canola | J42: 6685992 | K42: 28.9
G43: 2021 | H43: British Columbia | I43: Canola | J43: 103340 | K43: 28.6
G44: 2021 | H44: Manitoba | I44: Canola | J44: 3424226 | K44: 36.4
...
