Workbook

Sheet Data
A1: field_id | B1: fertilizer_kg_ha | C1: rainfall_mm | D1: variety | E1: yield_bu_acre
A2: C001 | B2: 146.2 | C2: 198.7 | D2: InVigor | E2: 56.7
A3: C002 | B3: 136.5 | C3: 282.3 | D3: DEKALB | E3: 62
A4: C003 | B4: 113.1 | C4: 273.6 | D4: Clearfield | E4: 53.6
A5: C004 | B5: 111.8 | C5: 173 | D5: InVigor | E5: 51.2
A6: C005 | B6: 102.6 | C6: 215.5 | D6: InVigor | E6: 49.2
A7: C006 | B7: 140.5 | C7: 151.1 | D7: InVigor | E7: 51.2
A8: C007 | B8: 102 | C8: 217 | D8: Clearfield | E8: 49
A9: C008 | B9: 136.8 | C9: 275.2 | D9: InVigor | E9: 56.8
A10: C009 | B10: 141.6 | C10: 258.5 | D10: InVigor | E10: 61
A11: C010 | B11: 97.9 | C11: 210.2 | D11: Clearfield | E11: 48.2
A12: C011 | B12: 154.6 | C12: 288.5 | D12: InVigor | E12: 59.5
A13: C012 | B13: 139.8 | D13: DEKALB | E13: 55.9
A14: C013 | B14: 111.6 | C14: 264.6 | D14: InVigor | E14: 55.2
A15: C014 | B15: 120.3 | C15: 186.7 | D15: InVigor | E15: 51.7
A16: C015 | B16: 147 | C16: 261.6 | D16: DEKALB | E16: 62.1
A17: C016 | B17: 104.6 | C17: 155.8 | D17: InVigor | E17: 42.5
A18: C017 | B18: 108.6 | C18: 242.9 | D18: DEKALB | E18: 44.9
A19: C018 | B19: 144.2 | C19: 232 | D19: DEKALB | E19: 61
A20: C019 | B20: 60.5 | C20: 155.7 | D20: DEKALB | E20: 40.6
A21: C020 | B21: 138.4 | C21: 274.1 | D21: Clearfield | E21: 58.9
A22: C021 | B22: 158.3 | C22: 243.3 | D22: DEKALB | E22: 56.8
A23: C022 | B23: 144.5 | C23: 232.2 | D23: Clearfield | E23: 54.5
A24: C023 | B24: 113.2 | C24: 265.8 | D24: Clearfield | E24: 51.1
A25: C024 | B25: 116 | C25: 241.8 | D25: InVigor | E25: 52.1
... A47: C046 | B47: 109.1 | C47: 231.5 | D47: DEKALB | E47: 45.3
A48: C047 | B48: 63.4 | D48: Clearfield | E48: 39.7
A49: C048 | B49: 125.9 | C49: 255.5 | D49: InVigor | E49: 55.6
A50: C049 | B50: 104.1 | C50: 173.3 | D50: DEKALB | E50: 44.9
A51: C050 | B51: 139.3 | C51: 208.9 | D51: InVigor | E51: 53.4
A52: C051 | B52: 139.1 | C52: 224.9 | D52: DEKALB | E52: 57.2
A53: C052 | B53: 145.2 | C53: 234.9 | D53: InVigor | E53: 59.5
A54: C053 | B54: 133.8 | C54: 180.9 | D54: DEKALB | E54: 51.8
A55: C054 | B55: 109.5 | C55: 209.3 | D55: DEKALB | E55: 50
A56: C055 | B56: 105.2 | C56: 220 | D56: Clearfield | E56: 52
A57: C056 | B57: 123 | C57: 216.5 | D57: Clearfield | E57: 49.3
A58: C057 | B58: 116.3 | C58: 172.4 | D58: Clearfield | E58: 51.6
A59: C058 | B59: 143.4 | C59: 211.4 | D59: Clearfield | E59: 51.5
A60: C059 | B60: 142.4 | C60: 231.1 | D60: InVigor | E60: 58.4
... A88: C087 | B88: 137.9 | C88: 242.5 | D88: InVigor | E88: 52.8
...

Sheet README
A1: Relationships in the canola trial
A2: One workbook for scatter plots, correlation and a simple linear model
A4: How to use this workbook
A5: Start with Scatter plots. Then use Correlation to put a number on each linear relationship. The Linear model sheet estimates the fertilizer-yield line and predicts the average yield at a fertilizer rate you choose. The green input cell is the one intended for editing.
A9: Sheet | B9: Purpose
A10: Data | B10: 120 canola fields used throughout Module 7
A11: Scatter plots | B11: Look at the point cloud before calculating
A12: Correlation | B12: Compare three Pearson correlations
A13: Linear model | B13: Estimate and use the fertilizer-yield line
A15: Source: practice/data/canola_trial.csv. Three rainfall values are missing; Excel's CORREL calculation uses the complete pairs available for each relationship.

Sheet Scatter plots
A1: Look before calculating
A2: Yield against fertilizer rate for 120 canola fields
A4: Check | B4: What the plot shows
A5: Overall pattern | B5: Positive and roughly linear, with substantial field-to-field scatter
A7: Fertilizer (kg/ha) | B7: Yield (bu/ac)
A8: =Data!B2 -> 146.2 | B8: =Data!E2 -> 56.7
A9: =Data!B3 -> 136.5 | B9: =Data!E3 -> 62
A10: =Data!B4 -> 113.1 | B10: =Data!E4 -> 53.6
A11: =Data!B5 -> 111.8 | B11: =Data!E5 -> 51.2
A12: =Data!B6 -> 102.6 | B12: =Data!E6 -> 49.2
A13: =Data!B7 -> 140.5 | B13: =Data!E7 -> 51.2
A14: =Data!B8 -> 102 | B14: =Data!E8 -> 49
A15: =Data!B9 -> 136.8 | B15: =Data!E9 -> 56.8
A16: =Data!B10 -> 141.6 | B16: =Data!E10 -> 61
A17: =Data!B11 -> 97.9 | B17: =Data!E11 -> 48.2
A18: =Data!B12 -> 154.6 | B18: =Data!E12 -> 59.5
A19: =Data!B13 -> 139.8 | B19: =Data!E13 -> 55.9
... A23: =Data!B17 -> 104.6 | B23: =Data!E17 -> 42.5
A24: =Data!B18 -> 108.6 | B24: =Data!E18 -> 44.9 | D24: Read the point cloud before you summarize it. Check its direction, shape, spread, unusual points and possible groups.
A25: =Data!B19 -> 144.2 | B25: =Data!E19 -> 61
A26: =Data!B20 -> 60.5 | B26: =Data!E20 -> 40.6
A27: =Data!B21 -> 138.4 | B27: =Data!E21 -> 58.9
A28: =Data!B22 -> 158.3 | B28: =Data!E22 -> 56.8
A29: =Data!B23 -> 144.5 | B29: =Data!E23 -> 54.5
A30: =Data!B24 -> 113.2 | B30: =Data!E24 -> 51.1
A31: =Data!B25 -> 116 | B31: =Data!E25 -> 52.1
A32: =Data!B26 -> 137.9 | B32: =Data!E26 -> 54.8
A33: =Data!B27 -> 90.7 | B33: =Data!E27 -> 47.3
A34: =Data!B28 -> 125.5 | B34: =Data!E28 -> 48.2
A35: =Data!B29 -> 112.1 | B35: =Data!E29 -> 52.3
A36: =Data!B30 -> 105 | B36: =Data!E30 -> 51.6
... A127: =Data!B121 -> 133.3 | B127: =Data!E121 -> 60.1

Sheet Correlation
A1: Correlation
A2: Pearson's r measures the direction and strength of a linear relationship
A4: Relationship | B4: Correlation (r) | C4: Excel formula | D4: Reading
A5: Fertilizer and yield | B5: =CORREL(Data!$B$2:$B$121,Data!$E$2:$E$121) -> 0.75357591 | C5: =CORREL(Data!B2:B121,Data!E2:E121) | D5: =IF(B5>0,"Positive",IF(B5<0,"Negative","No linear relationship")) -> Positive
A6: Rainfall and yield | B6: =CORREL(Data!$C$2:$C$121,Data!$E$2:$E$121) -> 0.64798046 | C6: =CORREL(Data!C2:C121,Data!E2:E121) | D6: =IF(B6>0,"Positive",IF(B6<0,"Negative","No linear relationship")) -> Positive
A7: Fertilizer and rainfall | B7: =CORREL(Data!$B$2:$B$121,Data!$C$2:$C$121) -> 0.46145455 | C7: =CORREL(Data!B2:B121,Data!C2:C121) | D7: =IF(B7>0,"Positive",IF(B7<0,"Negative","No linear relationship")) -> Positive
A10: Correlation describes a linear pattern. It does not show causation, and it can miss a strong curved relationship. Plot first.
A12: The fertilizer-yield correlation is about 0.754. Its square is the R² for the simple linear model on the next sheet.

Sheet Linear model
A1: A simple linear model
A2: Estimate yield from fertilizer rate, then check whether the prediction stays inside the observed range
A4: Quantity | B4: Value | C4: Excel formula | E4: Fertilizer (kg/ha) | F4: Yield (bu/ac)
A5: Slope (bu/ac per kg/ha) | B5: =SLOPE(Data!$E$2:$E$121,Data!$B$2:$B$121) -> 0.18141239 | C5: =SLOPE(Data!E2:E121,Data!B2:B121) | E5: =Data!B2 -> 146.2 | F5: =Data!E2 -> 56.7
A6: Intercept (bu/ac) | B6: =INTERCEPT(Data!$E$2:$E$121,Data!$B$2:$B$121) -> 30.698127 | C6: =INTERCEPT(Data!E2:E121,Data!B2:B121) | E6: =Data!B3 -> 136.5 | F6: =Data!E3 -> 62
A7: R² | B7: =RSQ(Data!$E$2:$E$121,Data!$B$2:$B$121) -> 0.56787665 | C7: =RSQ(Data!E2:E121,Data!B2:B121) | E7: =Data!B4 -> 113.1 | F7: =Data!E4 -> 53.6
A8: Minimum fertilizer (kg/ha) | B8: =MIN(Data!$B$2:$B$121) -> 58.3 | C8: =MIN(Data!B2:B121) | E8: =Data!B5 -> 111.8 | F8: =Data!E5 -> 51.2
A9: Maximum fertilizer (kg/ha) | B9: =MAX(Data!$B$2:$B$121) -> 186.9 | C9: =MAX(Data!B2:B121) | E9: =Data!B6 -> 102.6 | F9: =Data!E6 -> 49.2
E10: =Data!B7 -> 140.5 | F10: =Data!E7 -> 51.2
E11: =Data!B8 -> 102 | F11: =Data!E8 -> 49
A12: Prediction | B12: Value | C12: How it is calculated | E12: =Data!B9 -> 136.8 | F12: =Data!E9 -> 56.8
A13: Fertilizer rate (kg/ha) | B13: 120 | C13: Edit the green cell | E13: =Data!B10 -> 141.6 | F13: =Data!E10 -> 61
A14: Predicted average yield (bu/ac) | B14: =$B$6+$B$5*$B$13 -> 52.467614 | C14: =intercept + slope × fertilizer rate | E14: =Data!B11 -> 97.9 | F14: =Data!E11 -> 48.2
E15: =Data!B12 -> 154.6 | F15: =Data!E12 -> 59.5
E16: =Data!B13 -> 139.8 | F16: =Data!E13 -> 55.9
A17: The slope is an association, not automatically a causal effect. Predictions outside the observed fertilizer range are extrapolations, even though Excel will still calculate them. | E17: =Data!B14 -> 111.6 | F17: =Data!E14 -> 55.2
E18: =Data!B15 -> 120.3 | F18: =Data!E15 -> 51.7
E19: =Data!B16 -> 147 | F19: =Data!E16 -> 62.1
E20: =Data!B17 -> 104.6 | F20: =Data!E17 -> 42.5
E21: =Data!B18 -> 108.6 | F21: =Data!E18 -> 44.9
E22: =Data!B19 -> 144.2 | F22: =Data!E19 -> 61
E23: =Data!B20 -> 60.5 | F23: =Data!E20 -> 40.6
E24: =Data!B21 -> 138.4 | F24: =Data!E21 -> 58.9
E25: =Data!B22 -> 158.3 | F25: =Data!E22 -> 56.8
E26: =Data!B23 -> 144.5 | F26: =Data!E23 -> 54.5
E27: =Data!B24 -> 113.2 | F27: =Data!E24 -> 51.1
E28: =Data!B25 -> 116 | F28: =Data!E25 -> 52.1
E29: =Data!B26 -> 137.9 | F29: =Data!E26 -> 54.8
... E124: =Data!B121 -> 133.3 | F124: =Data!E121 -> 60.1
