Workbook

Sheet Canola data
A1: field_id | B1: fertilizer_kg_ha | C1: rainfall_mm | D1: variety | E1: yield_bu_acre
A2: C001 | B2: 146.2 | C2: 198.7 | D2: InVigor | E2: 56.7
A3: C002 | B3: 136.5 | C3: 282.3 | D3: DEKALB | E3: 62
A4: C003 | B4: 113.1 | C4: 273.6 | D4: Clearfield | E4: 53.6
A5: C004 | B5: 111.8 | C5: 173 | D5: InVigor | E5: 51.2
A6: C005 | B6: 102.6 | C6: 215.5 | D6: InVigor | E6: 49.2
A7: C006 | B7: 140.5 | C7: 151.1 | D7: InVigor | E7: 51.2
A8: C007 | B8: 102 | C8: 217 | D8: Clearfield | E8: 49
A9: C008 | B9: 136.8 | C9: 275.2 | D9: InVigor | E9: 56.8
A10: C009 | B10: 141.6 | C10: 258.5 | D10: InVigor | E10: 61
A11: C010 | B11: 97.9 | C11: 210.2 | D11: Clearfield | E11: 48.2
A12: C011 | B12: 154.6 | C12: 288.5 | D12: InVigor | E12: 59.5
A13: C012 | B13: 139.8 | D13: DEKALB | E13: 55.9
A14: C013 | B14: 111.6 | C14: 264.6 | D14: InVigor | E14: 55.2
A15: C014 | B15: 120.3 | C15: 186.7 | D15: InVigor | E15: 51.7
A16: C015 | B16: 147 | C16: 261.6 | D16: DEKALB | E16: 62.1
A17: C016 | B17: 104.6 | C17: 155.8 | D17: InVigor | E17: 42.5
A18: C017 | B18: 108.6 | C18: 242.9 | D18: DEKALB | E18: 44.9
A19: C018 | B19: 144.2 | C19: 232 | D19: DEKALB | E19: 61
A20: C019 | B20: 60.5 | C20: 155.7 | D20: DEKALB | E20: 40.6
A21: C020 | B21: 138.4 | C21: 274.1 | D21: Clearfield | E21: 58.9
A22: C021 | B22: 158.3 | C22: 243.3 | D22: DEKALB | E22: 56.8
A23: C022 | B23: 144.5 | C23: 232.2 | D23: Clearfield | E23: 54.5
A24: C023 | B24: 113.2 | C24: 265.8 | D24: Clearfield | E24: 51.1
A25: C024 | B25: 116 | C25: 241.8 | D25: InVigor | E25: 52.1
... A47: C046 | B47: 109.1 | C47: 231.5 | D47: DEKALB | E47: 45.3
A48: C047 | B48: 63.4 | D48: Clearfield | E48: 39.7
A49: C048 | B49: 125.9 | C49: 255.5 | D49: InVigor | E49: 55.6
A50: C049 | B50: 104.1 | C50: 173.3 | D50: DEKALB | E50: 44.9
A51: C050 | B51: 139.3 | C51: 208.9 | D51: InVigor | E51: 53.4
A52: C051 | B52: 139.1 | C52: 224.9 | D52: DEKALB | E52: 57.2
A53: C052 | B53: 145.2 | C53: 234.9 | D53: InVigor | E53: 59.5
A54: C053 | B54: 133.8 | C54: 180.9 | D54: DEKALB | E54: 51.8
A55: C054 | B55: 109.5 | C55: 209.3 | D55: DEKALB | E55: 50
A56: C055 | B56: 105.2 | C56: 220 | D56: Clearfield | E56: 52
A57: C056 | B57: 123 | C57: 216.5 | D57: Clearfield | E57: 49.3
A58: C057 | B58: 116.3 | C58: 172.4 | D58: Clearfield | E58: 51.6
A59: C058 | B59: 143.4 | C59: 211.4 | D59: Clearfield | E59: 51.5
A60: C059 | B60: 142.4 | C60: 231.1 | D60: InVigor | E60: 58.4
... A88: C087 | B88: 137.9 | C88: 242.5 | D88: InVigor | E88: 52.8
...

Sheet README
A1: Graphing in Excel
A2: Three worked charts use the canola variety trial from Module 02. Begin with the Bar chart sheet: its instructions show how to select the chart data and change the title, axes, legend, labels and colour.
A4: Sheet | B4: What to notice
A5: Bar chart | B5: Mean yield is calculated for each variety. Follow the numbered build and formatting instructions.
A6: Scatter plot | B6: Rainfall is placed on the horizontal axis and yield on the vertical axis.
A7: Histogram | B7: Formula-driven bins count the 120 field yields in 4 bu/ac intervals.
A8: Canola data | B8: One hundred twenty simulated canola fields with fertilizer, rainfall, variety and yield.
A10: Source: synthetic AREC 261 teaching data, practice/data/canola_trial.csv

Sheet Bar chart
A1: Build a bar chart of average yield by variety
A2: The chart uses only the Variety and Mean yield columns. Follow the numbered instructions below to build and format the chart in Excel.
A4: Variety | B4: Mean yield (bu/ac) | C4: Fields | D4: Formula in B
A5: InVigor | B5: =AVERAGEIF('Canola data'!$D$2:$D$121,A5,'Canola data'!$E$2:$E$121) -> 54.488095 | C5: =COUNTIF('Canola data'!$D$2:$D$121,A5) -> 42 | D5: =AVERAGEIF('Canola data'!$D$2:$D$121,A5,'Canola data'!$E$2:$E$121)
A6: Clearfield | B6: =AVERAGEIF('Canola data'!$D$2:$D$121,A6,'Canola data'!$E$2:$E$121) -> 53.458974 | C6: =COUNTIF('Canola data'!$D$2:$D$121,A6) -> 39 | D6: =AVERAGEIF('Canola data'!$D$2:$D$121,A6,'Canola data'!$E$2:$E$121)
A7: DEKALB | B7: =AVERAGEIF('Canola data'!$D$2:$D$121,A7,'Canola data'!$E$2:$E$121) -> 52.166667 | C7: =COUNTIF('Canola data'!$D$2:$D$121,A7) -> 39 | D7: =AVERAGEIF('Canola data'!$D$2:$D$121,A7,'Canola data'!$E$2:$E$121)
A10: Step | B10: Do this in Excel | C10: What it controls
A11: 1. Select the data | B11: Select A4:B7, including the two headers. Do not select Fields or Formula in B. | C11: One category column and one numeric series
A12: 2. Insert the chart | B12: Insert > Column or Bar Chart > Clustered Column. | C12: Excel calls vertical bars a column chart
A13: 3. Check the source | B13: Chart Design > Select Data. Varieties belong under Horizontal Axis Labels; Mean yield is the only series. | C13: Prevents an extra series or swapped rows and columns
A14: 4. Change the title | B14: Click the chart title and type: Average canola yield by variety. | C14: States the comparison
A15: 5. Add the y-axis title | B15: Chart Design > Add Chart Element > Axis Titles > Primary Vertical. Type: Mean yield (bu/ac). | C15: States the measure and unit
A16: 6. Alter the scale | B16: Right-click the y-axis numbers > Format Axis. Set Minimum = 0, Maximum = 60 and Major unit = 10. | C16: Keeps bar length proportional and makes ticks readable
A17: 7. Remove the legend | B17: Chart Design > Add Chart Element > Legend > None. | C17: One series does not need a legend
A18: 8. Add values if useful | B18: Chart Design > Add Chart Element > Data Labels > Outside End; format the labels to one decimal place. | C18: Shows exact means when there are only three bars
A19: 9. Format the bars | B19: Click one bar once to select the series, then set one fill colour. Avoid 3-D effects and heavy borders. | C19: Uses colour without implying three different variables

Sheet Scatter plot
A1: Rainfall and canola yield move together
A2: Each point is one simulated field. The horizontal position uses growing-season rainfall and the vertical position uses yield; three fields with missing rainfall do not produce a point.
A4: Element | B4: Meaning | C4: Source or check
A5: Horizontal position | B5: Growing-season rainfall in millimetres | C5: 'Canola data'!C2:C121
A6: Vertical position | B6: Yield in bushels per acre | C6: 'Canola data'!E2:E121
A7: Points plotted | B7: One field with both values recorded | C7: =COUNT('Canola data'!$C$2:$C$121) -> 117
A8: Missing rainfall | B8: Rows without rainfall are omitted | C8: =COUNTBLANK('Canola data'!$C$2:$C$121) -> 3
A9: Correlation | B9: A compact check on the positive linear relationship | C9: =CORREL('Canola data'!$C$2:$C$121,'Canola data'!$E$2:$E$121) -> 0.64798046
A12: Check | B12: Why | C12: In this chart
A13: Chart type | B13: An XY scatter chart treats rainfall as measured x-values. | C13: XY scatter, not a line chart
A14: Point count | B14: Missing observations should be disclosed. | C14: 117 plotted; 3 omitted
A15: Pattern | B15: A fitted line should not replace inspection of the points. | C15: Correlation is about 0.65

Sheet Histogram
A1: Distribution of canola trial yields
A2: The bin table counts yields in 4 bu/ac intervals. The final interval includes its upper boundary so every field is counted once.
A4: Lower bound | B4: Upper bound | C4: Fields | D4: Formula in C
A5: 38 | B5: 42 | C5: =COUNTIFS('Canola data'!$E$2:$E$121,">="&A5,'Canola data'!$E$2:$E$121,"<"&B5) -> 3 | D5: =COUNTIFS('Canola data'!$E$2:$E$121,">="&A5,'Canola data'!$E$2:$E$121,"<"&B5)
A6: 42 | B6: 46 | C6: =COUNTIFS('Canola data'!$E$2:$E$121,">="&A6,'Canola data'!$E$2:$E$121,"<"&B6) -> 9 | D6: =COUNTIFS('Canola data'!$E$2:$E$121,">="&A6,'Canola data'!$E$2:$E$121,"<"&B6)
A7: 46 | B7: 50 | C7: =COUNTIFS('Canola data'!$E$2:$E$121,">="&A7,'Canola data'!$E$2:$E$121,"<"&B7) -> 19 | D7: =COUNTIFS('Canola data'!$E$2:$E$121,">="&A7,'Canola data'!$E$2:$E$121,"<"&B7)
A8: 50 | B8: 54 | C8: =COUNTIFS('Canola data'!$E$2:$E$121,">="&A8,'Canola data'!$E$2:$E$121,"<"&B8) -> 36 | D8: =COUNTIFS('Canola data'!$E$2:$E$121,">="&A8,'Canola data'!$E$2:$E$121,"<"&B8)
A9: 54 | B9: 58 | C9: =COUNTIFS('Canola data'!$E$2:$E$121,">="&A9,'Canola data'!$E$2:$E$121,"<"&B9) -> 25 | D9: =COUNTIFS('Canola data'!$E$2:$E$121,">="&A9,'Canola data'!$E$2:$E$121,"<"&B9)
A10: 58 | B10: 62 | C10: =COUNTIFS('Canola data'!$E$2:$E$121,">="&A10,'Canola data'!$E$2:$E$121,"<"&B10) -> 18 | D10: =COUNTIFS('Canola data'!$E$2:$E$121,">="&A10,'Canola data'!$E$2:$E$121,"<"&B10)
A11: 62 | B11: 66 | C11: =COUNTIFS('Canola data'!$E$2:$E$121,">="&A11,'Canola data'!$E$2:$E$121,"<"&B11) -> 8 | D11: =COUNTIFS('Canola data'!$E$2:$E$121,">="&A11,'Canola data'!$E$2:$E$121,"<"&B11)
A12: 66 | B12: 70 | C12: =COUNTIFS('Canola data'!$E$2:$E$121,">="&A12,'Canola data'!$E$2:$E$121,"<"&B12) -> 1 | D12: =COUNTIFS('Canola data'!$E$2:$E$121,">="&A12,'Canola data'!$E$2:$E$121,"<"&B12)
A13: 70 | B13: 74 | C13: =COUNTIFS('Canola data'!$E$2:$E$121,">="&A13,'Canola data'!$E$2:$E$121,"<="&B13) -> 1 | D13: =COUNTIFS('Canola data'!$E$2:$E$121,">="&A13,'Canola data'!$E$2:$E$121,"<="&B13)
A16: Check | B16: Why | C16: In this chart
A17: Bin width | B17: Different bin widths can change the apparent shape. | C17: 4 bu/ac
A18: Count | B18: The bin counts should reconcile to the recorded values. | C18: =SUM(C5:C13) -> 120
A19: Range | B19: The first and last bins must contain the minimum and maximum. | C19: Observed range: 39.3 to 70.4 bu/ac
J25: Yield interval | K25: Fields
J26: 38--42 | K26: =C5 -> 3
J27: 42--46 | K27: =C6 -> 9
J28: 46--50 | K28: =C7 -> 19
J29: 50--54 | K29: =C8 -> 36
J30: 54--58 | K30: =C9 -> 25
J31: 58--62 | K31: =C10 -> 18
J32: 62--66 | K32: =C11 -> 8
J33: 66--70 | K33: =C12 -> 1
J34: 70--74 | K34: =C13 -> 1
