Workbook

Sheet Disclaimer
B6: Crop Planner (January 2026)
B7: An Excel version of the Ministry's Crop Planning Guides.
B8: COPYRIGHT:
B9: Government of Saskatchewan, 2026
B11: NOTICE:
B12: All rights reserved. Copyright and all other intellectual property rights for the Crop Planner, and
B13: all manuals, documentation and other material pertaining to this software, belong exclusively to the
B14: Government of Saskatchewan. This software is provided solely for the personal use of the
B15: purchaser under a non-exclusive license, and may not be copied, modified, published, sold or
B16: distributed to any third party, or transmitted in any form or by any mean whether electronic,
B17: mechanical, photocopying, recording or otherwise, in whole or in part, without the express
B18: written permission of the Saskatchewan Ministry of Agriculture.
... B23: loss or damage caused by or alleged to be caused by the use or operation of this software.

Sheet Guide2026
B2: Please do this page

Sheet General Assumptions
A1: General Assumptions for All Soil Zones
A2: 1. Crop prices are the average annual crop year farm gate price adopted from Agriculture and Agri-Food Canada’s most recent winter farm income forecast data or from reports of local grain buyers, vetted through regional crop specialists. The farm gate price represents the actual payment received by farmers. This includes crops sold through forward contracts and at spot prices. Crop prices can shift quickly and drastically due to market conditions, making information outdated within this guide. Producers should always check current prices and adjust figures as needed.
A3: 2. Targeted crop yields represent the five-year average of the 80th percentile of production for each crop in each soil zone. That is, for each of the past five years the point where 80 percent of producers would have attained a lower yield for that crop is determined (see the image below for an example).That value for each of the five years is then averaged. The calculation uses producer data submitted to Saskatchewan Crop Insurance Corporation and released each spring. These target yields reflect a higher level of management, improvements in plant genetics and enhanced nutrient and crop protection management. Producers should adjust the target yield to meet their goals and management style.
A4: 3. Seeding rates are determined by seed size, expected mortality, germination and desired plant population.
A5: 4. Seed costs are based on the use of certified seed and low disturbance direct seeding, collected from producers and vetted through regional crop experts.
A6: 5. Variety selection should be made to best suit the agro-climatic conditions. More information can be found by searching for Varieties of Grain Crops at saskatchewan.ca/crops.
A7: 6. Fertilizer needs are highly variable and must be adjusted to meet conditions. The calculations in this guide are based on most-recent prices from a selection of dealers throughout the province and the estimated amount of nutrients removed from the soil in order for the crop to attain the target yield. These are not recommended application rates for specific operations. The ministry encourages producers to soil test on a consistent basis in order to measure residual soil fertility and calculate the total crop nutrient application required to achieve targeted crop yields. This is consistent with 4R Nutrient Stewardship management practices. It is recommended to follow the guidelines for safe rates of fertilizer placed with the seed when determining the right rate of all nutrients. For pulse crops, producers should focus on applying the correct inoculant. Producers are reminded to adjust both the volume of nutrients applied and the price of each nutrient.
A8: 7. Crop protection efforts must be adjusted to meet each producer’s conditions. The assumptions in this guide cover common applications to demonstrate potential costs. These are not recommended crop protection applications for specific operations. Producers must cost their individual responses to weed, insect and disease pressures. Please refer to the Guide to Crop Protection available at saskatchewan.ca/crops for registered pest control products. The costs of crop protection products are calculated using the full registered rate of application and suggested retail prices from a selection of dealers across the province. Prices can vary significantly by vendor. Insect and disease control efforts will be aided by extended crop rotations, which reduce yield losses due to disease. Extended crop rotations also help ensure that management tools, such as resistant varieties and fungicides, remain effective by reducing selection pressure on the pathogen population. This guide assumes that commonly encountered insects or crop diseases are controlled through the use of the appropriate product given the crop and insect or disease combinations. Weed control efforts presented reflect the practice of herbicide layering as much as possible. Herbicide layering helps prevent and manage herbicide-resistant weed populations. Layering may involve the use of two or more modes of action for control of some weeds. The timing and number of applications used to estimate herbicide costs are indicated in a chart on each crop’s specific page. Below are the descriptions to the applications in the chart: • Pre-harvest: Pre-harvest glyphosate treatment to the previous crop. The benefit of perennial weed control from this application accrues to the crop that is planted after the application. • Fall application: Post-harvest fall application. Typically for winter annual weeds. The benefit of this application will also accrue to the crop that is planted after the application. • Pre-seed: Pre-seed burn off that replaces tillage in a low-disturbance direct seeding system. There are two windows of application presented in the chart which represent one or two herbicides used at the pre-seed timing where the primary activity is on emerged weeds. Soil-active herbicides that may be mixed with the burn off applications are treated separately below. Typically, the first application will be glyphosate. When glyphosate is applied alone, it is assumed that this is done at 360 grams of acid equivalent (active) per acre. If a second application is indicated, this will be a tank mix partnered with glyphosate for burn off purposes and has limited residual impact, if any. In a tank mix, the rate of glyphosate is assumed to be 180 grams acid equivalent (active) per acre. • Soil application: Soil-active herbicide that provides residual soil activity for control of emerging weeds beyond emergence and into the crop growth period. These are typically added for herbicide resistance management but also to contribute to increased crop yields by eliminating early weeds. Rates of some soil-active herbicides are adjusted for typical organic matter levels in the different soil zones. • In-crop: In-crop foliar application opportunities are provided for up to three herbicides. These are applied either in a mix or as separate sequential applications where tank mixing is not compatible. There are three windows of application allotted as indicated by each column in the chart. • Desiccation: Harvest aid application prior to harvest. This is done for the purpose of rapid dry down of the crop to facilitate timely harvest. This does not include glyphosate, which may be included as a mix with some harvest aid options.
A9: 8. Machinery operating costs include fuel usage and repair. Fuel costs are based on estimated fuel consumptions for the various farming operations with diesel fuel priced at $1.181/litre. Machinery repair rates are based on the Ministry’s 2024-25 Farm Machinery Custom and Rental Rate Guide and are set at 2.6 per cent of the yearly machinery investment cost.
A10: 9. Custom work and hired labour is made up of costs for custom farm operations, such as custom trucking and custom spraying. Skilled labour is assumed to be $28.00 per hour for 2026.
A11: 10. Crop insurance premiums are the five-year average of the premiums paid by producers who attain the targeted yield for the soil zone. The premiums used in this guide do not reflect actual producers’ costs given surcharges and taxes.
A12: 11. Hail Insurance premiums are based on the 2025 estimated average coverage per acre of $400 multiplied by a rate of 3.5 percent = $14.00/acre.
... A23: 22. Specialty crops can have limited market access due to demand. Growers wishing to add specialty crops to their rotation are encouraged to consider production contracts for the crop they grow. Contracts can help manage the risks associated with growing and marketing specialty crops.

Sheet Summary Calculator
A1: Summary of "My Farm"
B2: Instructions on using this sheet
A3: 1 | B3: This sheet provides a summary of your total projected farm financial situation.
A4: 2 | B4: Please go to the sheets for the crops you grow or you plan to grow and input your numbers in the "my farm" column. The data from those sheets will automatically appear in this summary calculator.
A5: 3 | B5: In this summary calcaulator, please input the total acres of each crop you grow or plan to grow.
A6: 4 | B6: The total colum will update automatically and provide your summary picture.
B9: Coarse Grains
C10: Total | D10: Feed Barley | E10: Acres | F10: Malt Barley | G10: Acres | H10: Corn | I10: Acres | J10: Fall Rye | K10: Acres | L10: Oats | M10: Acres | N10: Durum | O10: Acres | P10: Spring Wheat | Q10: Acres | R10: Winter Wheat | S10: Acres
B11: Total Revenue ($) | C11: =D11*E11+F11*G11+H11*I11+J11*K11++L11*M11++N11*O11+P11*Q11+R11*S11 | D11: =FBarley!$B$9 | F11: =MBarley!$B$9 | H11: =Corn!$B$9 | J11: =HFallRye!$B$9 | L11: =Oats!$B$9 | N11: =Durum!$B$9 | P11: =SWheat!$B$9 | R11: =WWheat!$B$9
B12: Total Variable Expenses ($) | C12: =D12*E11+F12*G11+H12*I11+J12*K11+L12*M11++N12*O11+P12*Q11+R12*S11 | D12: =FBarley!$B$28 | F12: =MBarley!$B$28 | H12: =Corn!$B$28 | J12: =HFallRye!$B$28 | L12: =Oats!$B$28 | N12: =Durum!$B$28 | P12: =SWheat!$B$28 | R12: =WWheat!$B$28
B13: Total Other Expenses* ($) | C13: =D13*E11+F13*G11+H13*I11+J13*K11+L13*M11++N13*O11+P13*Q11+R13*S11 | D13: =FBarley!$B$39 | F13: =MBarley!$B$39 | H13: =Corn!$B$39 | J13: =HFallRye!$B$39 | L13: =Oats!$B$39 | N13: =Durum!$B$39 | P13: =SWheat!$B$39 | R13: =WWheat!$B$39
B14: Total Expenses ($) | C14: =SUM(C12:C13)
B15: Total Acres | C15: =E11+G11+I11+K11+M11+O11+Q11+S11
B17: Oilseeds
C18: Total | D18: Canola | E18: Acres | F18: Flax | G18: Acres | H18: Brown Mustard | I18: Acres | J18: Oriental Mustard | K18: Acres | L18: Yellow Mustard | M18: Acres | N18: Hybrid Mustard | O18: Acres | P18: Sunflower | Q18: Acres
B19: Total Revenue ($) | C19: =D19*E19+F19*G19+V27*W27+H19*I19+J19*K19++L19*M19+N19*O19+P19*Q19 | D19: =Canola!$B$9 | F19: 0 | H19: =BMustard!$B$9 | J19: =OMustard!$B$9 | L19: =YMustard!$B$9 | N19: ='Hybrid Brown Mustard'!$B$9 | P19: =Sunflower!$B$9
B20: Total Variable Expenses ($) | C20: =D20*E19+F20*G19+V28*W27+H20*I19+J20*K19+L20*M19+N20*O19+P20*Q19 | D20: =Canola!$B$28 | F20: =Flax!$B$28 | H20: =BMustard!$B$28 | J20: =OMustard!$B$28 | L20: =YMustard!$B$28 | N20: ='Hybrid Brown Mustard'!$B$28 | P20: =Sunflower!$B$28
B21: Total Other Expenses* ($) | C21: =D21*E19+F21*G19+V29*W27+H21*I19+J21*K19+L21*M19+N21*O19+P21*Q19 | D21: =Canola!$B$39 | F21: =Flax!$B$39 | H21: =BMustard!$B$39 | J21: =OMustard!$B$39 | L21: =YMustard!$B$39 | N21: ='Hybrid Brown Mustard'!$B$39 | P21: =Sunflower!$B$39
B22: Total Expenses ($) | C22: =SUM(C20:C21)
B23: Total Acres | C23: =E19+G19+W27+I19+K19+M19+O19+Q19
B25: Pulses
C26: Total | D26: Desi Chickpeas | E26: Acres | F26: Large Chickpeas | G26: Acres | H26: Small Chickpeas | I26: Acres | J26: Large Green Lentil | K26: Acres | L26: Red Lentil | M26: Acres | N26: Green Peas | O26: Acres | P26: Yellow Peas | Q26: Acres | R26: Black Bean | S26: Acres | T26: Fababean | U26: Acres | V26: Soybean | W26: Acres
B27: Total Revenue ($) | C27: =T27*U27+J27*K27+L27*M27+N27*O27+P27*Q27+D27*E27+F27*G27+H27*I27+R27*S27+V27*W27 | D27: =DesiChickpeas!$B$9 | F27: ='Chickpeas, large'!$B$9 | H27: ='Chickpeas, small'!B$9 | J27: =LGLentil!$B$9 | L27: =RLentil!$B$9 | N27: =GPeas!$B$9 | P27: =Ypeas!$B$9 | R27: ='Black Bean'!$B$9 | T27: =Fbean!$B$9 | V27: =Soybean!$B$9
B28: Total Variable Expenses ($) | C28: =T28*U27+J28*K27+L28*M27+N28*O27+P28*Q27+D28*E27+F28*G27+H28*I27+R28*S27+V28*W27 | D28: =DesiChickpeas!$B$28 | F28: ='Chickpeas, large'!$B$28 | H28: ='Chickpeas, small'!B$28 | J28: =LGLentil!$B$28 | L28: =RLentil!$B$28 | N28: =GPeas!$B$28 | P28: =Ypeas!$B$28 | R28: ='Black Bean'!$B$28 | T28: =Fbean!$B$28 | V28: =Soybean!$B$28
B29: Total Other Expenses* ($) | C29: =T29*U27+J29*K27+L29*M27+N29*O27+P29*Q27+D29*E27+F29*G27+H29*I27+R29*S27+V29*W27 | D29: =DesiChickpeas!$B$39 | F29: ='Chickpeas, large'!$B$39 | H29: ='Chickpeas, small'!B$39 | J29: =LGLentil!$B$39 | L29: =RLentil!$B$39 | N29: =GPeas!$B$39 | P29: =Ypeas!$B$39 | R29: ='Black Bean'!$B$39 | T29: =Fbean!$B$39 | V29: =Soybean!$B$39
B30: Total Expenses($) | C30: =SUM(C28:C29)
B31: Total Acres | C31: =U27+K27+M27+O27+Q27+E27+G27+I27+S27+W27
B33: Specialty Crops
C34: Total | D34: Camelina | E34: Acres | F34: Canary | G34: Acres | H34: Caraway** | I34: Acres | J34: Coriander | K34: Acres | L34: Fenugreek | M34: Acres | N34: Quinoa | O34: Acres
B35: Total Revenue ($) | C35: =D35*E35+F35*G35+H35*I35+J35*K35+L35*M35+N35*O35+P19*Q19 | D35: =Camelina!$B$9 | F35: =Canaryseed!$B$9 | H35: =Caraway!$B$9 | J35: =Coriander!$B$9 | L35: =Fenugreek!$B$9 | N35: =Quinoa!$B$9
B36: Total Variable Expenses ($) | C36: =D36*E35+F36*G35+H36*I35+J36*K35+L36*M35+N36*O35+P20*Q19 | D36: =Camelina!$B$28 | F36: =Canaryseed!$B$28 | H36: =Caraway!$B$28 | J36: =Coriander!$B$28 | L36: =Fenugreek!$B$28 | N36: =Quinoa!$B$28
B37: Total Other Expenses* ($) | C37: =D37*E35+F37*G35+H37*I35+J37*K35+L37*M35+N37*O35+P21*Q19 | D37: =Camelina!$B$39 | F37: =Canaryseed!$B$39 | H37: =Caraway!$B$39 | J37: =Coriander!$B$39 | L37: =Fenugreek!$B$39 | N37: =Quinoa!$B$39
B38: Total Expenses($) | C38: =SUM(C36:C37)
B39: Total Acres | C39: =E35+G35+I35+K35+M35+O35+Q19
B41: Farm Total
B42: Total Revenue ($) | C42: =SUM(C11,C19,C27,C35)
B43: Total Variable Expenses ($) | C43: =SUM(C12,C20,C28,C36)
B44: Total Other Expenses* ($) | C44: =SUM(C13,C21,C29,C37)
B45: Total Expenses ($) | C45: =SUM(C14,C22,C30,C38)
B46: Return over variable expenses ($) | C46: =C42-C43
...

Sheet MBarley
A1: MALT BARLEY PRODUCTION COSTS ($/ACRE) FOR SASKATCHEWAN 2026
C2: Economics | F2: Agronomics
A3: CROP | D3: MALT BARLEY | F3: Seeding: Seeding rates are based on a target plant stand in plants per square foot. This guide assumes a producer will seed to achieve 25 plants per square foot in the black soil zone, 22 in the dark brown soil zone and 20 in the brown soil zone, with a thousand kernel weight of 45 grams and 85 per cent emergence. Fertilization: Fertility costs are based on nutrient removal rates given the targeted crop yield. These are: 78 lb./ac. N and 34 lb./ac. P2O5 for the black soil zone, 66 lb./ac. N and 29 lb./ac. P2O5 for the dark brown soil zone and 50 lb./ac. N and 22 lb./ac. P2O5 for the brown soil zone. Producers are encouraged to use their own rates based on soil tests. Producers may fertilize malting barley less trying to avoid protein being too high. Crop Rotation: Diverse crop rotations are recommended to help reduce disease pressure and suppress weeds to manage herbicide resistance. Barley is a very competitive crop that will suppress growth of weeds. Crop Protection Insect control: Cutworms, aphids, thrips, mites, grasshoppers, armyworm, slugs and wireworms might require control. Seed treatments are available for wireworm control. Disease control: Cereal crops can be affected by both leaf diseases and fusarium head blight (FHB). When disease pressure is moderate, a single application at FHB timing can be effective in managing both types of diseases. This estimation includes the cost of a single fungicide application. When disease pressure is high, an additional fungicide application for leaf diseases may be required. Fungicide applications should be made based on field history and disease risk during the growing season. Weed control: Because barley is competitive, growers can often reduce the number of herbicide applications from those listed. A soil-applied herbicide was used to manage Group 1 resistant wild oats. Refer to the Guide to Crop Protection available at saskatchewan.ca/crops for more information about Group 1 resistance. Herbicide costs are based on the following herbicide timings. Please refer to general assumptions for details. Please insert herbicide application window.
B4: My Farm | D4: 80th percentile | I4: Average Yield
A5: Soil Zone | C5: Brown | D5: Dark Brown | E5: Black | I5: Brown | J5: Dark Brown | K5: Black
A6: REVENUE PER ACRE
A7: Estimated Yield (bu./ac) (A) | C7: 46.625288 | D7: 61.698019 | E7: 73.471465 | I7: 29.297009 | J7: 44.442236 | K7: 59.028588
A8: Est. On Farm Market Price $/bu. (B) | C8: 5.787793 | D8: 5.787793 | E8: 5.787793 | I8: =C8 | J8: =D8 | K8: =E8
A9: Estimated Gross Revenue/ac (AxB)=C | B9: =ROUND((B8*B7),2) | C9: =ROUND((C8*C7),2) | D9: =ROUND((D8*D7),2) | E9: =ROUND((E8*E7),2) | I9: =ROUND((I8*I7),2) | J9: =ROUND((J8*J7),2) | K9: =ROUND((K8*K7),2)
A11: EXPENSES PER ACRE
A12: Variable Expenses/acre
A13: Seed | C13: 21.311 | D13: 23.632 | E13: 26.797 | I13: =C13 | J13: =D13 | K13: =E13
A14: -Seed Treatments/Inoculants | C14: 7.5145728 | D14: 8.3329916 | E14: 9.4490173 | I14: =C14 | J14: =D14 | K14: =E14
A15: Fertilizer -Nitrogen (N) | C15: 40.933481 | D15: 54.032194 | E15: 63.85623 | I15: =C15 | J15: =D15 | K15: =E15
A16: -Phosphorous (P2O5) | C16: 21.144666 | D16: 27.872514 | E16: 32.678119 | I16: =C16 | J16: =D16 | K16: =E16
A17: -Sulphur and Other | C17: 0 | D17: 0 | E17: 0 | I17: =C17 | J17: =D17 | K17: =E17
A18: Plant Protection -Herbicides | C18: 78.98 | D18: 78.98 | E18: 83.31 | I18: =C18 | J18: =D18 | K18: =E18
A19: -Insecticides | C19: 19.41299 | D19: 19.41299 | E19: 19.41299 | I19: =C19 | J19: =D19 | K19: =E19
A20: -Fungicides | C20: 15.99 | D20: 15.99 | E20: 15.99 | I20: =C20 | J20: =D20 | K20: =E20
A21: Machinery Operating -Fuel | C21: 16.061797 | D21: 20.077246 | E21: 25.096558 | I21: =C21 | J21: =D21 | K21: =E21
A22: -Repair | C22: 11.563288 | D22: 13.039497 | E22: 14.757902 | I22: =C22 | J22: =D22 | K22: =E22
A23: Custom Work and Hired Labour | C23: 22 | D23: 22.25 | E23: 22.25 | I23: =C23 | J23: =D23 | K23: =E23
A24: Crop Insurance Premium | C24: 8.781674 | D24: 6.848361 | E24: 5.227862 | I24: =C24 | J24: =D24 | K24: =E24
... A27: Interest on Variable Expenses | C27: 10.681787 | D27: 11.747628 | E27: 12.855053 | I27: =C27 | J27: =D27 | K27: =E27
A28: Total Variable Expenses (D) | B28: =SUM(B13:B27) | C28: =SUM(C13:C27) | D28: =SUM(D13:D27) | E28: =SUM(E13:E27) | I28: =SUM(I13:I27) | J28: =SUM(J13:J27) | K28: =SUM(K13:K27)
A30: Other Expenses/acre
A31: Building Repair | C31: 0.74456846 | D31: 0.97564143 | E31: 1.3350883 | I31: =C31 | J31: =D31 | K31: =E31
A32: Property Taxes | C32: 5.0765336 | D32: 6.6426982 | E32: 10.072059 | I32: =C32 | J32: =D32 | K32: =E32
A33: Business Overhead | C33: 2.6074747 | D33: 3.9864277 | E33: 4.6759042 | I33: =C33 | J33: =D33 | K33: =E33
A34: Machinery Depreciation | C34: 47.587379 | D34: 53.662547 | E34: 60.734445 | I34: =C34 | J34: =D34 | K34: =E34
A35: Building Depreciation | C35: 1.45 | D35: 1.9 | E35: 2.6 | I35: =C35 | J35: =D35 | K35: =E35
A36: Machinery Investment | C36: 30.020076 | D36: 33.852541 | E36: 38.313785 | I36: =C36 | J36: =D36 | K36: =E36
A37: Building Investment | C37: 1.3262667 | D37: 1.7378667 | E37: 2.3781333 | I37: =C37 | J37: =D37 | K37: =E37
A38: Land Investment | C38: 70.104 | D38: 80.6565 | E38: 75.38025 | I38: =C38 | J38: =D38 | K38: =E38
A39: Total Other Expenses (E) | B39: =SUM(B31:B38) | C39: =SUM(C31:C38) | D39: =SUM(D31:D38) | E39: =SUM(E31:E38) | I39: =SUM(I31:I38) | J39: =SUM(J31:J38) | K39: =SUM(K31:K38)
A40: Labour and Management (F)*
A41: Total Expenses (D+E+F)=(G) | B41: =B28+B39+B40 | C41: =C28+C39+C40 | D41: =D28+D39+D40 | E41: =E28+E39+E40 | I41: =I28+I39+I40 | J41: =J28+J39+J40 | K41: =K28+K39+K40
A43: RETURNS PER ACRE
A44: Return over Variable Expenses (C-D) | B44: =B9-B28 | C44: =C9-C28 | D44: =D9-D28 | E44: =E9-E28 | I44: =I9-I28 | J44: =J9-J28 | K44: =K9-K28
A45: Return over Total Expenses (C-G) | B45: =B9-B41 | C45: =C9-C41 | D45: =D9-D41 | E45: =E9-E41 | I45: =I9-I41 | J45: =J9-J41 | K45: =K9-K41
...

Sheet FBarley
A1: FEED BARLEY PRODUCTION COSTS ($/ACRE) FOR SASKATCHEWAN 2026
C2: Economics | F2: Agronomics
A3: CROP | D3: FEED BARLEY | F3: Seeding: Seeding rates are based on a target plant stand in plants per square foot. This guide assumes a producer will seed to achieve 25 plants per square foot in the black soil zone, 22 in the dark brown soil zone and 20 in the brown soil zone, with a thousand kernel weight of 45 grams and 85 per cent emergence. Fertilization: Fertility costs are based on nutrient removal rates given the targeted crop yield. These are: 96 lb./ac. N and 42 lb./ac. P2O5 for the black soil zone, 80 lb./ac. N and 35 lb./ac. P2O5 for the dark brown soil zone and 61 lb./ac. N and 26 lb./ac. P2O5 for the brown soil zone. Producers are encouraged to use their own rates based on soil tests. Crop Rotation: Diverse crop rotations are recommended to help reduce disease pressure and suppress weeds to manage herbicide resistance. Barley is a very competitive crop that will suppress growth of weeds. Feed barley markets may be more tolerant of weed escapes than malt barley. Crop Protection Insect control: Cutworms, aphids, thrips, mites, grasshoppers, armyworm, slugs and wireworms might require control. Seed treatments are available for wireworm control. Disease control: Cereal crops can be affected by both leaf diseases and fusarium head blight (FHB). When disease pressure is moderate, a single application at FHB timing can be effective in managing both types of diseases. This estimation includes the cost of a single fungicide application in the black soil zone. When disease pressure is high, an additional fungicide application for leaf diseases may be required. Fungicide applications should be made based on field history and disease risk during the growing season. Weed control: Because barley is competitive, growers can often reduce the number of herbicide applications from those listed. Herbicide costs are based on the following herbicide timings. Please refer to general assumptions for details. Please insert herbicide application window.
B4: My Farm | D4: 80th percentile | I4: Average Yield
A5: Soil Zone | C5: Brown | D5: Dark Brown | E5: Black | I5: Brown | J5: Dark Brown | K5: Black
A6: REVENUE PER ACRE
A7: Estimated Yield (bu./ac) (A) | C7: 56.99913 | D7: 75.333357 | E7: 90.4821 | I7: 35.815414 | J7: 54.264025 | K7: 72.695306
A8: Est. On Farm Market Price $/bu. (B) | C8: 5.0257638 | D8: 5.0257638 | E8: 5.0257638 | I8: 5.0257638 | J8: 5.0257638 | K8: =E8
A9: Estimated Gross Revenue/ac (AxB)=C | B9: =ROUND((B8*B7),2) | C9: =ROUND((C8*C7),2) | D9: =ROUND((D8*D7),2) | E9: =ROUND((E8*E7),2) | I9: =ROUND((I8*I7),2) | J9: =ROUND((J8*J7),2) | K9: =ROUND((K8*K7),2)
A11: EXPENSES PER ACRE
A12: Variable Expenses/acre
A13: Seed | C13: 21.412 | D13: 23.744 | E13: 26.924 | I13: =C13 | J13: =D13 | K13: =E13
A14: -Seed Treatments/Inoculants | C14: 7.5145728 | D14: 8.3329916 | E14: 9.4490173 | I14: =C14 | J14: =D14 | K14: =E14
A15: Fertilizer -Nitrogen (N) | C15: 49.938846 | D15: 65.493569 | E15: 78.592283 | I15: =C15 | J15: =D15 | K15: =E15
A16: -Phosphorous (P2O5) | C16: 24.98915 | D16: 33.639241 | E16: 40.367089 | I16: =C16 | J16: =D16 | K16: =E16
A17: -Sulphur and Other | C17: 0 | D17: 0 | E17: 0 | I17: =C17 | J17: =D17 | K17: =E17
A18: Plant Protection -Herbicides | C18: 28.37458 | D18: 28.37458 | E18: 28.37458 | I18: =C18 | J18: =D18 | K18: =E18
A19: -Insecticides | C19: 18.7118 | D19: 18.7118 | E19: 18.7118 | I19: =C19 | J19: =D19 | K19: =E19
A20: -Fungicides | C20: 0 | D20: 0 | E20: 15.99 | I20: =C20 | J20: =D20 | K20: =E20
A21: Machinery Operating -Fuel | C21: 16.061797 | D21: 20.077246 | E21: 25.096558 | I21: =C21 | J21: =D21 | K21: =E21
A22: -Repair | C22: 11.563288 | D22: 13.039497 | E22: 14.757902 | I22: =C22 | J22: =D22 | K22: =E22
A23: Custom Work and Hired Labour | C23: 22 | D23: 22.25 | E23: 22.25 | I23: =C23 | J23: =D23 | K23: =E23
A24: Crop Insurance Premium | C24: 8.781674 | D24: 6.848361 | E24: 5.227862 | I24: =C24 | J24: =D24 | K24: =E24
... A27: Interest on Variable Expenses | C27: 8.6238941 | D27: 9.8559411 | E27: 11.60225 | I27: =C27 | J27: =D27 | K27: =E27
A28: Total Variable Expenses (D) | B28: =SUM(B13:B27) | C28: =SUM(C13:C27) | D28: =SUM(D13:D27) | E28: =SUM(E13:E27) | I28: =SUM(I13:I27) | J28: =SUM(J13:J27) | K28: =SUM(K13:K27)
A30: Other Expenses/acre
A31: Building Repair | C31: 0.74456846 | D31: 0.97564143 | E31: 1.3350883 | I31: =C31 | J31: =D31 | K31: =E31
A32: Property Taxes | C32: 5.0765336 | D32: 6.6426982 | E32: 10.072059 | I32: =C32 | J32: =D32 | K32: =E32
A33: Business Overhead | C33: 2.6074747 | D33: 3.9864277 | E33: 4.6759042 | I33: =C33 | J33: =D33 | K33: =E33
A34: Machinery Depreciation | C34: 47.587379 | D34: 53.662547 | E34: 60.734445 | I34: =C34 | J34: =D34 | K34: =E34
A35: Building Depreciation | C35: 1.45 | D35: 1.9 | E35: 2.6 | I35: =C35 | J35: =D35 | K35: =E35
A36: Machinery Investment | C36: 30.020076 | D36: 33.852541 | E36: 38.313785 | I36: =C36 | J36: =D36 | K36: =E36
A37: Building Investment | C37: 1.3262667 | D37: 1.7378667 | E37: 2.3781333 | I37: =C37 | J37: =D37 | K37: =E37
A38: Land Investment | C38: 70.104 | D38: 80.6565 | E38: 75.38025 | I38: =C38 | J38: =D38 | K38: =E38
A39: Total Other Expenses (E) | B39: =SUM(B31:B38) | C39: =SUM(C31:C38) | D39: =SUM(D31:D38) | E39: =SUM(E31:E38) | I39: =SUM(I31:I38) | J39: =SUM(J31:J38) | K39: =SUM(K31:K38)
A40: Labour and Management (F)*
A41: Total Expenses (D+E+F)=(G) | B41: =B28+B39+B40 | C41: =C28+C39+C40 | D41: =D28+D39+D40 | E41: =E28+E39+E40 | I41: =I28+I39+I40 | J41: =J28+J39+J40 | K41: =K28+K39+K40
A43: RETURNS PER ACRE
A44: Return over Variable Expenses (C-D) | B44: =B9-B28 | C44: =C9-C28 | D44: =D9-D28 | E44: =E9-E28 | I44: =I9-I28 | J44: =J9-J28 | K44: =K9-K28
A45: Return over Total Expenses (C-G) | B45: =B9-B41 | C45: =C9-C41 | D45: =D9-D41 | E45: =E9-E41 | I45: =I9-I41 | J45: =J9-J41 | K45: =K9-K41
...

Sheet Corn
A1: CORN PRODUCTION COSTS ($/ACRE) FOR SASKATCHEWAN 2026
C2: Economics | F2: Agronomics
A3: CROP | D3: CORN | F3: Variety Selection: Corn varieties are not listed in the Varieties of Grain Crops found on saskatchewan.ca/crops. Please contact your retailer for more information. Seeding: A plant population of 30,000 plants/ac. is used for all three soil zones. Fertilization: Fertility costs are based on nutrient removal rates given the targeted crop yield. These are: 107 lb./ac. N and 48 lb./ac. P2O5 for the black soil zone and 87 lb./ac. N and 31 lb./ac. P2O5 in the dark brown soil zone and 57 lb./ac. N and 25 lb./ac. P2O5 in the brown soil zone. Producers are encouraged to use their own rates based on soil tests. Crop Rotation: Extended crop rotations can be used to reduce disease pressure by allowing infected residue to decompose between host crops. This is particularly important for residue- borne diseases caused by bacteria, such as Goss’s Wilt, as fungicides will not protect against this disease. Corn is not competitive with weeds. Some herbicide choices in corn can significantly restrict cropping options the following year. Crop Protection Insect control: Cutworms, wireworms, seedcorn maggot, corn rootworm, aphids, spider mite, grasshoppers, European corn borer, corn earworm and armyworms might require control. Seed treatments are available for wireworm and seedcorn maggot control. Varieties resistant to European corn borer, corn earworm, and corn rootworm are available. Disease control: The cost of fungicide is not included in this estimate. Disease risk assessment is encouraged to guide fungicide application decisions. Weed control: Corn must be kept free of weeds until 10 leaf tips are visible to prevent significant yield losses. Herbicide costs are based on the following herbicide timings. Please refer to general assumptions for details. Please insert herbicide application window.
B4: My Farm | D4: 80th percentile | I4: Average Yield
A5: Soil Zone | C5: Brown | D5: Dark Brown | E5: Black | I5: Brown | J5: Dark Brown | K5: Black
A6: REVENUE PER ACRE
A7: Estimated Yield (bu./ac) (A) | C7: 52.873506 | D7: 81.649232 | E7: 99.876616 | I7: 24.695145 | J7: 47.709253 | K7: 74.879776
A8: Est. On Farm Market Price $/bu. (B) | C8: 5.23 | D8: 5.23 | E8: 5.23 | I8: =C8 | J8: =D8 | K8: =E8
A9: Estimated Gross Revenue/ac (AxB)=C | B9: =ROUND((B8*B7),2) | C9: =ROUND((C8*C7),2) | D9: =ROUND((D8*D7),2) | E9: =ROUND((E8*E7),2) | I9: =ROUND((I8*I7),2) | J9: =ROUND((J8*J7),2) | K9: =ROUND((K8*K7),2)
A11: EXPENSES PER ACRE
A12: Variable Expenses/acre
A13: Seed | C13: 109.8 | D13: 109.8 | E13: 109.8 | I13: =C13 | J13: =D13 | K13: =E13
A14: -Seed Treatments/Inoculants | C14: 24.3 | D14: 24.3 | E14: 24.3 | I14: =C14 | J14: =D14 | K14: =E14
A15: Fertilizer -Nitrogen (N) | C15: 46.664168 | D15: 71.224256 | E15: 87.597649 | I15: =C15 | J15: =D15 | K15: =E15
A16: -Phosphorous (P2O5) | C16: 24.028029 | D16: 29.794756 | E16: 46.133816 | I16: =C16 | J16: =D16 | K16: =E16
A17: -Sulphur and Other | C17: 0 | D17: 0 | E17: 0 | I17: =C17 | J17: =D17 | K17: =E17
A18: Plant Protection -Herbicides | C18: 50.440524 | D18: 34.708024 | E18: 50.440524 | I18: =C18 | J18: =D18 | K18: =E18
A19: -Insecticides | C19: 22.626525 | D19: 22.626525 | E19: 22.626525 | I19: =C19 | J19: =D19 | K19: =E19
A20: -Fungicides | C20: 0 | D20: 0 | E20: 0 | I20: =C20 | J20: =D20 | K20: =E20
A21: Machinery Operating -Fuel | C21: 17.95142 | D21: 22.439275 | E21: 28.049094 | I21: =C21 | J21: =D21 | K21: =E21
A22: -Repair | C22: 15.233142 | D22: 16.709351 | E22: 18.427756 | I22: =C22 | J22: =D22 | K22: =E22
A23: Custom Work and Hired Labour | C23: 50.23891 | D23: 46.67592 | E23: 59.4644 | I23: =C23 | J23: =D23 | K23: =E23
A24: Crop Insurance Premium | C24: 10.376433 | D24: 10.315374 | E24: 3.654 | I24: =C24 | J24: =D24 | K24: =E24
... A27: Interest on Variable Expenses | C27: 14.770087 | D27: 15.46332 | E27: 17.840885 | I27: =C27 | J27: =D27 | K27: =E27
A28: Total Variable Expenses (D) | B28: =SUM(B13:B27) | C28: =SUM(C13:C27) | D28: =SUM(D13:D27) | E28: =SUM(E13:E27) | I28: =SUM(I13:I27) | J28: =SUM(J13:J27) | K28: =SUM(K13:K27)
A30: Other Expenses/acre
A31: Building Repair | C31: 0.74456846 | D31: 0.97564143 | E31: 1.3350883 | I31: =C31 | J31: =D31 | K31: =E31
A32: Property Taxes | C32: 5.0765336 | D32: 6.6426982 | E32: 10.072059 | I32: =C32 | J32: =D32 | K32: =E32
A33: Business Overhead | C33: 2.6074747 | D33: 3.9864277 | E33: 4.6759042 | I33: =C33 | J33: =D33 | K33: =E33
A34: Machinery Depreciation | C34: 62.690236 | D34: 68.765404 | E34: 75.837302 | I34: =C34 | J34: =D34 | K34: =E34
A35: Building Depreciation | C35: 1.45 | D35: 1.9 | E35: 2.6 | I35: =C35 | J35: =D35 | K35: =E35
A36: Machinery Investment | C36: 39.547579 | D36: 43.380045 | E36: 47.841289 | I36: =C36 | J36: =D36 | K36: =E36
A37: Building Investment | C37: 1.3262667 | D37: 1.7378667 | E37: 2.3781333 | I37: =C37 | J37: =D37 | K37: =E37
A38: Land Investment | C38: 70.104 | D38: 80.6565 | E38: 75.38025 | I38: =C38 | J38: =D38 | K38: =E38
A39: Total Other Expenses (E) | B39: =SUM(B31:B38) | C39: =SUM(C31:C38) | D39: =SUM(D31:D38) | E39: =SUM(E31:E38) | I39: =SUM(I31:I38) | J39: =SUM(J31:J38) | K39: =SUM(K31:K38)
A40: Labour and Management (F)*
A41: Total Expenses (D+E+F)=(G) | B41: =B28+B39+B40 | C41: =C28+C39+C40 | D41: =D28+D39+D40 | E41: =E28+E39+E40 | I41: =I28+I39+I40 | J41: =J28+J39+J40 | K41: =K28+K39+K40
A43: RETURNS PER ACRE
A44: Return over Variable Expenses (C-D) | B44: =B9-B28 | C44: =C9-C28 | D44: =D9-D28 | E44: =E9-E28 | I44: =I9-I28 | J44: =J9-J28 | K44: =K9-K28
A45: Return over Total Expenses (C-G) | B45: =B9-B41 | C45: =C9-C41 | D45: =D9-D41 | E45: =E9-E41 | I45: =I9-I41 | J45: =J9-J41 | K45: =K9-K41
...

Sheet HFallRye
A1: HYBRID FALL RYE PRODUCTION COSTS ($/ACRE) FOR SASKATCHEWAN 2026
C2: Economics | F2: Agronomics
A3: CROP | D3: HYBRID FALL RYE | F3: Seeding: Certified seed is needed every year for hybrids. A seeding rate of 0.8 units/ac. is used for all soil zones. One unit is equal to one million viable seeds. Fertilization: Fertility costs are based on nutrient removal rates given the targeted crop yield. These are: 91 lb./ac N and 38 lb./ac. P2O5 for the black soil zone, 74lb./ac. N and 31 lb./ac. P2O5 for the dark brown soil zone and 47 lb./ac. N and 20 lb./ac. P2O5 for the brown soil zone. Producers are encouraged to use their own rates based on soil tests. Crop Rotation: Diverse crop rotations are recommended to help reduce disease pressure and suppress weeds to manage herbicide resistance. Fall rye is a very competitive crop that will suppress growth of spring germinating weeds. Crop Protection Insect control: Cutworms, aphids, thrips, mites, grasshoppers, armyworm, slugs and wireworms might require control. Seed treatments are available for wireworm control. Disease control: The cost of fungicide is not included in this estimate. Disease risk assessment is encouraged to guide fungicide application decisions. Weed control: Rye has very few herbicide options. Herbicide costs are based on the following herbicide timings. Please refer to general assumptions for details. Please insert herbicide application window.
B4: My Farm | D4: 80th percentile | I4: Average Yield
A5: Soil Zone | C5: Brown | D5: Dark Brown | E5: Black | I5: Brown | J5: Dark Brown | K5: Black
A6: REVENUE PER ACRE
A7: Estimated Yield (bu./ac) (A) | C7: 40.15536 | D7: 63.38248 | E7: 77.94864 | I7: 24.4 | J7: 46.1 | K7: 55.9
A8: Est. On Farm Market Price $/bu. (B) | C8: 4.83 | D8: 4.83 | E8: 4.83 | I8: =C8 | J8: =D8 | K8: =E8
A9: Estimated Gross Revenue/ac (AxB)=C | B9: =ROUND((B8*B7),2) | C9: =ROUND((C8*C7),2) | D9: =ROUND((D8*D7),2) | E9: =ROUND((E8*E7),2) | I9: =ROUND((I8*I7),2) | J9: =ROUND((J8*J7),2) | K9: =ROUND((K8*K7),2)
A11: EXPENSES PER ACRE
A12: Variable Expenses/acre
A13: Seed | C13: 60 | D13: 60 | E13: 60 | I13: =C13 | J13: =D13 | K13: =E13
A14: -Seed Treatments/Inoculants | C14: 0 | D14: 0 | E14: 0 | I14: =C14 | J14: =D14 | K14: =E14
A15: Fertilizer -Nitrogen (N) | C15: 38.477472 | D15: 60.581551 | E15: 74.498935 | I15: =C15 | J15: =D15 | K15: =E15
A16: -Phosphorous (P2O5) | C16: 19.222423 | D16: 29.794756 | E16: 36.522604 | I16: =C16 | J16: =D16 | K16: =E16
A17: -Sulphur and Other | C17: 0 | D17: 0 | E17: 0 | I17: =C17 | J17: =D17 | K17: =E17
A18: Plant Protection -Herbicides | C18: 31.03 | D18: 31.03 | E18: 31.03 | I18: =C18 | J18: =D18 | K18: =E18
A19: -Insecticides | C19: 0 | D19: 0 | E19: 0 | I19: =C19 | J19: =D19 | K19: =E19
A20: -Fungicides | C20: 0 | D20: 0 | E20: 0 | I20: =C20 | J20: =D20 | K20: =E20
A21: Machinery Operating -Fuel | C21: 16.061797 | D21: 20.077246 | E21: 25.096558 | I21: =C21 | J21: =D21 | K21: =E21
A22: -Repair | C22: 11.563288 | D22: 13.039497 | E22: 14.757902 | I22: =C22 | J22: =D22 | K22: =E22
A23: Custom Work and Hired Labour | C23: 22 | D23: 22 | E23: 22.25 | I23: =C23 | J23: =D23 | K23: =E23
A24: Crop Insurance Premium | C24: 8.901632 | D24: 7.7294131 | E24: 6.1515743 | I24: =C24 | J24: =D24 | K24: =E24
... A27: Interest on Variable Expenses | C27: 19.2256 | D27: 22.494616 | E27: 24.790128 | I27: =C27 | J27: =D27 | K27: =E27
A28: Total Variable Expenses (D) | B28: =SUM(B13:B27) | C28: =SUM(C13:C27) | D28: =SUM(D13:D27) | E28: =SUM(E13:E27) | I28: =SUM(I13:I27) | J28: =SUM(J13:J27) | K28: =SUM(K13:K27)
A30: Other Expenses/acre
A31: Building Repair | C31: 0.74456846 | D31: 0.97564143 | E31: 1.3350883 | I31: =C31 | J31: =D31 | K31: =E31
A32: Property Taxes | C32: 5.0765336 | D32: 6.6426982 | E32: 10.072059 | I32: =C32 | J32: =D32 | K32: =E32
A33: Business Overhead | C33: 2.6074747 | D33: 3.9864277 | E33: 4.6759042 | I33: =C33 | J33: =D33 | K33: =E33
A34: Machinery Depreciation | C34: 47.587379 | D34: 53.662547 | E34: 60.734445 | I34: =C34 | J34: =D34 | K34: =E34
A35: Building Depreciation | C35: 1.45 | D35: 1.9 | E35: 2.6 | I35: =C35 | J35: =D35 | K35: =E35
A36: Machinery Investment | C36: 30.020076 | D36: 33.852541 | E36: 38.313785 | I36: =C36 | J36: =D36 | K36: =E36
A37: Building Investment | C37: 1.3262667 | D37: 1.7378667 | E37: 2.3781333 | I37: =C37 | J37: =D37 | K37: =E37
A38: Land Investment | C38: 70.104 | D38: 80.6565 | E38: 75.38025 | I38: =C38 | J38: =D38 | K38: =E38
A39: Total Other Expenses (E) | B39: =SUM(B31:B38) | C39: =SUM(C31:C38) | D39: =SUM(D31:D38) | E39: =SUM(E31:E38) | I39: =SUM(I31:I38) | J39: =SUM(J31:J38) | K39: =SUM(K31:K38)
A40: Labour and Management (F)*
A41: Total Expenses (D+E+F)=(G) | B41: =B28+B39+B40 | C41: =C28+C39+C40 | D41: =D28+D39+D40 | E41: =E28+E39+E40 | I41: =I28+I39+I40 | J41: =J28+J39+J40 | K41: =K28+K39+K40
A43: RETURNS PER ACRE
A44: Return over Variable Expenses (C-D) | B44: =B9-B28 | C44: =C9-C28 | D44: =D9-D28 | E44: =E9-E28 | I44: =I9-I28 | J44: =J9-J28 | K44: =K9-K28
A45: Return over Total Expenses (C-G) | B45: =B9-B41 | C45: =C9-C41 | D45: =D9-D41 | E45: =E9-E41 | I45: =I9-I41 | J45: =J9-J41 | K45: =K9-K41
...

Sheet Oats
A1: OATS PRODUCTION COSTS ($/ACRE) FOR SASKATCHEWAN 2026
C2: Economics | F2: Agronomics
A3: CROP | D3: OATS | F3: Seeding: A seed rate of 127 lb./ac. is used in the black soil zone, 106 lb./ac. in the dark brown soil zone and 85 lb./ac. in the brown soil zone. Seeding rates are based on a target plant stand in plants per square foot. This guide assumes a producer will seed to achieve 20 plants per square meter in the brown soil zone, 25 plants per square meter in the dark brown soil zone and 30 plants per square meter in the black soil zone, 37.5 thousand kernel weight and 85 percent emergence. Fertilization: Fertility costs are based on nutrient removal rates given the targeted crop yield. These are: 89 lb./ac. N and 36 lb./ac. P2O5 for the black soil zone, 58 lb./ac. N and 24 lb./ac. P2O5 for the dark brown soil zone and 33 lb./ac. N and 13 lb./ac. P2O5 for the brown soil zone. Producers are encouraged to use their own rates based on soil tests. Crop Rotation: Diverse crop rotations are recommended to help reduce disease pressure as well as suppress weeds to manage herbicide resistance. Oats are a very competitive crop that will suppress growth of spring germinating weeds. Wild oats cannot be controlled in tame oats with herbicides. Crop Protection Insect control: Cutworms, aphids, thrips, mites, grasshoppers, armyworm, slugs and wireworms might require control. Seed treatments are available for wireworm control. Disease control: Leaf diseases may result in yield losses in oat crops. Fungicide application can be used to protect leaf tissue from disease infection. This estimation includes the cost of a single fungicide application in the black soil zone. Fungicide application should be based on disease pressure in the field. Weed control: Because oats are very competitive, growers can often reduce the number of herbicide applications from those listed. Some buyers of milling oats do not allow use of pre-harvest glyphosate in their contracts. Herbicide costs are based on the following herbicide timings. Please refer to general assumptions for details. Please insert herbicide application window.
B4: My Farm | D4: 80th percentile | I4: Average Yield
A5: Soil Zone | C5: Brown | D5: Dark Brown | E5: Black | I5: Brown | J5: Dark Brown | K5: Black
A6: REVENUE PER ACRE
A7: Estimated Yield (bu./ac) (A) | C7: 47.98308 | D7: 84.94302 | E7: 130.33242 | I7: 26.58522 | J7: 56.41254 | K7: 97.263
A8: Est. On Farm Market Price $/bu. (B) | C8: 3.791267 | D8: 3.791267 | E8: 3.791267 | I8: =C8 | J8: =D8 | K8: =E8
A9: Estimated Gross Revenue/ac (AxB)=C | B9: =ROUND((B8*B7),2) | C9: =ROUND((C8*C7),2) | D9: =ROUND((D8*D7),2) | E9: =ROUND((E8*E7),2) | I9: =ROUND((I8*I7),2) | J9: =ROUND((J8*J7),2) | K9: =ROUND((K8*K7),2)
A11: EXPENSES PER ACRE
A12: Variable Expenses/acre
A13: Seed | C13: 22.015 | D13: 27.454 | E13: 32.893 | I13: =C13 | J13: =D13 | K13: =E13
A14: -Seed Treatments/Inoculants | C14: 6.3241454 | D14: 7.8865814 | E14: 9.4490173 | I14: =C14 | J14: =D14 | K14: =E14
A15: Fertilizer -Nitrogen (N) | C15: 27.016097 | D15: 47.482838 | E15: 72.861596 | I15: =C15 | J15: =D15 | K15: =E15
A16: -Phosphorous (P2O5) | C16: 12.494575 | D16: 23.066908 | E16: 34.600362 | I16: =C16 | J16: =D16 | K16: =E16
A17: -Sulphur and Other | C17: 0 | D17: 0 | E17: 0 | I17: =C17 | J17: =D17 | K17: =E17
A18: Plant Protection -Herbicides | C18: 30.76 | D18: 30.76 | E18: 30.76 | I18: =C18 | J18: =D18 | K18: =E18
A19: -Insecticides | C19: 0 | D19: 0 | E19: 0 | I19: =C19 | J19: =D19 | K19: =E19
A20: -Fungicides | C20: 0 | D20: 0 | E20: 15.99 | I20: =C20 | J20: =D20 | K20: =E20
A21: Machinery Operating -Fuel | C21: 16.061797 | D21: 20.077246 | E21: 25.096558 | I21: =C21 | J21: =D21 | K21: =E21
A22: -Repair | C22: 11.563288 | D22: 13.039497 | E22: 14.757902 | I22: =C22 | J22: =D22 | K22: =E22
A23: Custom Work and Hired Labour | C23: 22 | D23: 22.25 | E23: 22.25 | I23: =C23 | J23: =D23 | K23: =E23
A24: Crop Insurance Premium | C24: 9.0871701 | D24: 9.9398824 | E24: 8.417862 | I24: =C24 | J24: =D24 | K24: =E24
... A27: Interest on Variable Expenses | C27: 6.6538567 | D27: 8.396017 | E27: 10.895477 | I27: =C27 | J27: =D27 | K27: =E27
A28: Total Variable Expenses (D) | B28: =SUM(B13:B27) | C28: =SUM(C13:C27) | D28: =SUM(D13:D27) | E28: =SUM(E13:E27) | I28: =SUM(I13:I27) | J28: =SUM(J13:J27) | K28: =SUM(K13:K27)
A30: Other Expenses/acre
A31: Building Repair | C31: 0.74456846 | D31: 0.97564143 | E31: 1.3350883 | I31: =C31 | J31: =D31 | K31: =E31
A32: Property Taxes | C32: 5.0765336 | D32: 6.6426982 | E32: 10.072059 | I32: =C32 | J32: =D32 | K32: =E32
A33: Business Overhead | C33: 2.6074747 | D33: 3.9864277 | E33: 4.6759042 | I33: =C33 | J33: =D33 | K33: =E33
A34: Machinery Depreciation | C34: 47.587379 | D34: 53.662547 | E34: 60.734445 | I34: =C34 | J34: =D34 | K34: =E34
A35: Building Depreciation | C35: 1.45 | D35: 1.9 | E35: 2.6 | I35: =C35 | J35: =D35 | K35: =E35
A36: Machinery Investment | C36: 30.020076 | D36: 33.852541 | E36: 38.313785 | I36: =C36 | J36: =D36 | K36: =E36
A37: Building Investment | C37: 1.3262667 | D37: 1.7378667 | E37: 2.3781333 | I37: =C37 | J37: =D37 | K37: =E37
A38: Land Investment | C38: 70.104 | D38: 80.6565 | E38: 75.38025 | I38: =C38 | J38: =D38 | K38: =E38
A39: Total Other Expenses (E) | B39: =SUM(B31:B38) | C39: =SUM(C31:C38) | D39: =SUM(D31:D38) | E39: =SUM(E31:E38) | I39: =SUM(I31:I38) | J39: =SUM(J31:J38) | K39: =SUM(K31:K38)
A40: Labour and Management (F)**
A41: Total Expenses (D+E+F)=(G) | B41: =B28+B39+B40 | C41: =C28+C39+C40 | D41: =D28+D39+D40 | E41: =E28+E39+E40 | I41: =I28+I39+I40 | J41: =J28+J39+J40 | K41: =K28+K39+K40
A43: RETURNS PER ACRE
A44: Return over Variable Expenses (C-D) | B44: =B9-B28 | C44: =C9-C28 | D44: =D9-D28 | E44: =E9-E28 | I44: =I9-I28 | J44: =J9-J28 | K44: =K9-K28
A45: Return over Total Expenses (C-G) | B45: =B9-B41 | C45: =C9-C41 | D45: =D9-D41 | E45: =E9-E41 | I45: =I9-I41 | J45: =J9-J41 | K45: =K9-K41
...

Sheet Durum
A1: DURUM PRODUCTION COSTS ($/ACRE) FOR SASKATCHEWAN 2026
C2: Economics | E2: Agronomics
A3: CROP | C3: DURUM | E3: Seeding: Seeding rates are based on a target plant stand in plants per square foot. This guide assumes a producer will seed to achieve 22 plants per square foot in the dark brown soil zone and 20 in the brown soil zone, with a thousand kernel weight of 42.1 grams and 85 per cent emergence. Durum is recommended in the brown and dark brown soil zones. Fertilization: Fertility costs are based on nutrient removal rates given the targeted crop yield. These are: 95 lb./ac. N and 37 lb./ac. P2O5 for the dark brown soil zone and 67 lb./ac. N and 27 lb./ac. P2O5 for the brown soil zone. Producers are encouraged to use their own rates based on soil tests. Crop Rotation: Diverse crop rotations are recommended to help reduce disease pressure and suppress weed growth. Like all cereals, durum is a relatively competitive crop against weeds. Crop Protection Insect control: Wheat midge, cutworms, aphids, thrips, mite, grasshoppers, armyworms, slugs, wheat stem sawfly and wireworms might require control. Varietal blends with resistance are available if heavy wheat midge pressures are anticipated. Wheat stem sawfly resistant varieties are available. Seed treatments are available for wireworm control. An insecticide application to control wheat midge is assumed, but in practice should be made based on scouting to determine economic risk. No insecticide applications for wheat midge would be required for midge tolerant varieties. Disease control: Cereal crops can be affected by both leaf diseases and fusarium head blight (FHB). When disease pressure is moderate, a single application at FHB timing can be effective in managing both types of diseases. This estimation includes the cost of a single fungicide application. When disease pressure is high an additional fungicide application for leaf diseases might be required. Fungicide applications should be made based on field history and disease risk during the growing season. Weed control: Durum lacks many options for soil-applied herbicides for herbicide layering programs. Herbicide costs are based on the following herbicide timings. Please refer to general assumptions for details. Please insert herbicide application window.
B4: My Farm | C4: 80th percentile | H4: Average Yield
A5: Soil Zone | C5: Brown | D5: Dark Brown | H5: Brown | I5: Dark Brown
A6: REVENUE PER ACRE
A7: Estimated Yield (bu./ac) (A) | C7: 40.896072 | D7: 57.589426 | H7: 26.096678 | I7: 43.812676
A8: Est. On Farm Market Price $/bu. (B) | C8: 7.8357464 | D8: 7.8357464 | H8: =C8 | I8: =D8
A9: Estimated Gross Revenue/ac (AxB)=C | B9: =ROUND((B8*B7),2) | C9: =ROUND((C8*C7),2) | D9: =ROUND((D8*D7),2) | H9: =ROUND((H8*H7),2) | I9: =ROUND((I8*I7),2)
A11: EXPENSES PER ACRE
A12: Variable Expenses/acre
A13: Seed | C13: 22.42 | D13: 24.544 | H13: =C13 | I13: =D13
A14: -Seed Treatments/Inoculants | C14: 7.0681625 | D14: 7.7377779 | H14: =C14 | I14: =D14
A15: Fertilizer -Nitrogen (N) | C15: 54.850864 | D15: 77.773613 | H15: =C15 | I15: =D15
A16: -Phosphorous (P2O5) | C16: 25.950271 | D16: 35.561483 | H16: =C16 | I16: =D16
A17: -Sulphur and Other | C17: 0 | D17: 0 | H17: =C17 | I17: =D17
A18: Plant Protection -Herbicides | C18: 21.72 | D18: 21.72 | H18: =C18 | I18: =D18
A19: -Insecticides | C19: 6.4761905 | D19: 6.4761905 | H19: =C19 | I19: =D19
A20: -Fungicides | C20: 15.99 | D20: 15.99 | H20: =C20 | I20: =D20
A21: Machinery Operating -Fuel | C21: 16.061797 | D21: 20.077246 | H21: =C21 | I21: =D21
A22: -Repair | C22: 11.563288 | D22: 13.039497 | H22: =C22 | I22: =D22
A23: Custom Work and Hired Labour | C23: 23.5 | D23: 23.25 | H23: =C23 | I23: =D23
A24: Crop Insurance Premium | C24: 9.704645 | D24: 10.580618 | H24: =C24 | I24: =D24
... A27: Interest on Variable Expenses | C27: 8.8494852 | D27: 10.470863 | H27: =C27 | I27: =D27
A28: Total Variable Expenses (D) | B28: =SUM(B13:B27) | C28: =SUM(C13:C27) | D28: =SUM(D13:D27) | H28: =SUM(H13:H27) | I28: =SUM(I13:I27)
A30: Other Expenses/acre
A31: Building Repair | C31: 0.74456846 | D31: 0.97564143 | H31: =C31 | I31: =D31
A32: Property Taxes | C32: 5.0765336 | D32: 6.6426982 | H32: =C32 | I32: =D32
A33: Business Overhead | C33: 2.6074747 | D33: 3.9864277 | H33: =C33 | I33: =D33
A34: Machinery Depreciation | C34: 47.587379 | D34: 53.662547 | H34: =C34 | I34: =D34
A35: Building Depreciation | C35: 1.45 | D35: 1.9 | H35: =C35 | I35: =D35
A36: Machinery Investment | C36: 30.020076 | D36: 33.852541 | H36: =C36 | I36: =D36
A37: Building Investment | C37: 1.3262667 | D37: 1.7378667 | H37: =C37 | I37: =D37
A38: Land Investment | C38: 70.104 | D38: 80.6565 | H38: =C38 | I38: =D38
A39: Total Other Expenses (E) | B39: =SUM(B31:B38) | C39: =SUM(C31:C38) | D39: =SUM(D31:D38) | H39: =SUM(H31:H38) | I39: =SUM(I31:I38)
A40: Labour and Management (F)*
A41: Total Expenses (D+E+F)=(G) | B41: =B28+B39+B40 | C41: =C28+C39+C40 | D41: =D28+D39+D40 | H41: =H28+H39+H40 | I41: =I28+I39+I40
A43: RETURNS PER ACRE
A44: Return over Variable Expenses (C-D) | B44: =B9-B28 | C44: =C9-C28 | D44: =D9-D28 | H44: =H9-H28 | I44: =I9-I28
A45: Return over Total Expenses (C-G) | B45: =B9-B41 | C45: =C9-C41 | D45: =D9-D41 | H45: =H9-H41 | I45: =I9-I41
...

Sheet SWheat
A1: HARD RED SPRING WHEAT PRODUCTION COSTS ($/ACRE) FOR SASKATCHEWAN 2026
C2: Economics | F2: Agronomics
A3: CROP | D3: HARD RED SPRING WHEAT | F3: Seeding: Seeding rates are based on a target plant stand in plants per square foot. This guide assumes a producer will seed to achieve 25 plants per square foot in the black soil zone, 22 in the dark brown soil zone and 20 in the brown soil zone, with a thousand kernel weight of 34.5 grams and 85 per cent emergence. Fertilization: Fertility costs are based on nutrient removal rates given the target yield. These are: 110 lb./ac. N and 43 lb./ac. P2O5 for the black soil zone, 91 lb./ac. N and 36 lb./ac. P2O5 for the dark brown soil zone and 73 lb./ac. N and 29 lb./ac. P2O5 for the brown soil zone. Producers are encouraged to use their own rates based on soil tests. Crop Rotation: Rotation plays an important role in the suppression of weed growth. A break between cereal crops will help reduce disease pressure by allowing infested crop residue to decompose. Crop Protection Insect control: Wheat midge, cutworms, aphids, thrips, mites, grasshoppers, armyworms, slugs, wheat stem sawfly and wireworms might require control. An insecticide application to control wheat midge is assumed, but in practice should be made based on scouting to determine economic risk. No insecticide application for wheat midge would be required for midge tolerant varieties. Please refer to the Guide to Crop Protection available at saskatchewan.ca/crops for registered pest control products for specific pests. Disease control: Cereal crops can be affected by both leaf diseases and fusarium head blight (FHB). When disease pressure is moderate, a single application at FHB timing can be effective in managing both types of diseases. This estimation includes the cost of a single fungicide application. When disease pressure is high, an additional fungicide application for leaf diseases may be required. Fungicide applications should be made based on field history and disease risk during the growing season. Weed control: Spring wheat has many herbicide options to choose from. Herbicide costs are based on the following herbicide timings. Please refer to general assumptions for details. Please insert herbicide application window.
B4: My Farm | D4: 80th percentile | I4: Average Yield
A5: Soil Zone | C5: Brown | D5: Dark Brown | E5: Black | I5: Brown | J5: Dark Brown | K5: Black
A6: REVENUE PER ACRE
A7: Estimated Yield (bu./ac) (A) | C7: 43.98574 | D7: 54.895536 | E7: 66.837336 | I7: 30.148494 | J7: 41.653142 | K7: 53.847529
A8: Est. On Farm Market Price $/bu. (B) | C8: 7 | D8: 7 | E8: 7 | I8: =C8 | J8: =D8 | K8: =E8
A9: Estimated Gross Revenue/ac (AxB)=C | B9: =ROUND((B8*B7),2) | C9: =ROUND((C8*C7),2) | D9: =ROUND((D8*D7),2) | E9: =ROUND((E8*E7),2) | I9: =ROUND((I8*I7),2) | J9: =ROUND((J8*J7),2) | K9: =ROUND((K8*K7),2)
A11: EXPENSES PER ACRE
A12: Variable Expenses/acre
A13: Seed | C13: 17.316 | D13: 19.092 | E13: 21.534 | I13: =C13 | J13: =D13 | K13: =E13
A14: -Seed Treatments/Inoculants | C14: 5.8033335 | D14: 6.3985471 | E14: 7.216966 | I14: =C14 | J14: =D14 | K14: =E14
A15: Fertilizer -Nitrogen (N) | C15: 59.762882 | D15: 74.498935 | E15: 90.053657 | I15: =C15 | J15: =D15 | K15: =E15
A16: -Phosphorous (P2O5) | C16: 27.872514 | D16: 34.600362 | E16: 41.32821 | I16: =C16 | J16: =D16 | K16: =E16
A17: -Sulphur and Other | C17: 0 | D17: 0 | E17: 0 | I17: =C17 | J17: =D17 | K17: =E17
A18: Plant Protection -Herbicides | C18: 59.36 | D18: 63.34 | E18: 63.94 | I18: =C18 | J18: =D18 | K18: =E18
A19: -Insecticides | C19: 6.4761905 | D19: 6.4761905 | E19: 6.4761905 | I19: =C19 | J19: =D19 | K19: =E19
A20: -Fungicides | C20: 15.99 | D20: 15.99 | E20: 15.99 | I20: =C20 | J20: =D20 | K20: =E20
A21: Machinery Operating -Fuel | C21: 16.061797 | D21: 20.077246 | E21: 25.096558 | I21: =C21 | J21: =D21 | K21: =E21
A22: -Repair | C22: 11.563288 | D22: 13.039497 | E22: 14.757902 | I22: =C22 | J22: =D22 | K22: =E22
A23: Custom Work and Hired Labour | C23: 23.5 | D23: 23.25 | E23: 24.25 | I23: =C23 | J23: =D23 | K23: =E23
A24: Crop Insurance Premium | C24: 6.2654523 | D24: 5.6596652 | E24: 4.9985592 | I24: =C24 | J24: =D24 | K24: =E24
... A27: Interest on Variable Expenses | C27: 10.16218 | D27: 11.442977 | E27: 12.7345 | I27: =C27 | J27: =D27 | K27: =E27
A28: Total Variable Expenses (D) | B28: =SUM(B13:B27) | C28: =SUM(C13:C27) | D28: =SUM(D13:D27) | E28: =SUM(E13:E27) | I28: =SUM(I13:I27) | J28: =SUM(J13:J27) | K28: =SUM(K13:K27)
A30: Other Expenses/acre
A31: Building Repair | C31: 0.74456846 | D31: 0.97564143 | E31: 1.3350883 | I31: =C31 | J31: =D31 | K31: =E31
A32: Property Taxes | C32: 5.0765336 | D32: 6.6426982 | E32: 10.072059 | I32: =C32 | J32: =D32 | K32: =E32
A33: Business Overhead | C33: 2.6074747 | D33: 3.9864277 | E33: 4.6759042 | I33: =C33 | J33: =D33 | K33: =E33
A34: Machinery Depreciation | C34: 47.587379 | D34: 53.662547 | E34: 60.734445 | I34: =C34 | J34: =D34 | K34: =E34
A35: Building Depreciation | C35: 1.45 | D35: 1.9 | E35: 2.6 | I35: =C35 | J35: =D35 | K35: =E35
A36: Machinery Investment | C36: 30.020076 | D36: 33.852541 | E36: 38.313785 | I36: =C36 | J36: =D36 | K36: =E36
A37: Building Investment | C37: 1.3262667 | D37: 1.7378667 | E37: 2.3781333 | I37: =C37 | J37: =D37 | K37: =E37
A38: Land Investment | C38: 70.104 | D38: 80.6565 | E38: 75.38025 | I38: =C38 | J38: =D38 | K38: =E38
A39: Total Other Expenses (E) | B39: =SUM(B31:B38) | C39: =SUM(C31:C38) | D39: =SUM(D31:D38) | E39: =SUM(E31:E38) | I39: =SUM(I31:I38) | J39: =SUM(J31:J38) | K39: =SUM(K31:K38)
A40: Labour and Management (F)*
A41: Total Expenses (D+E+F)=(G) | B41: =B28+B39+B40 | C41: =C28+C39+C40 | D41: =D28+D39+D40 | E41: =E28+E39+E40 | I41: =I28+I39+I40 | J41: =J28+J39+J40 | K41: =K28+K39+K40
A43: RETURNS PER ACRE
A44: Return over Variable Expenses (C-D) | B44: =B9-B28 | C44: =C9-C28 | D44: =D9-D28 | E44: =E9-E28 | I44: =I9-I28 | J44: =J9-J28 | K44: =K9-K28
A45: Return over Total Expenses (C-G) | B45: =B9-B41 | C45: =C9-C41 | D45: =D9-D41 | E45: =E9-E41 | I45: =I9-I41 | J45: =J9-J41 | K45: =K9-K41
...

Sheet WWheat
A1: WINTER WHEAT PRODUCTION COSTS ($/ACRE) FOR SASKATCHEWAN 2026
C2: Economics | F2: Agronomics
A3: CROP | D3: WINTER WHEAT | F3: Seeding: Seeding rates are based on a target plant stand in plants per square foot. This guide assumes a producer will seed to achieve 30 plants per square foot in the black soil zone, 28 in the dark brown soil zone and 25 in the brown soil zone, with a thousand kernel weight of 36 grams and 85 per cent emergence. Fertilization: Fertility costs are based on nutrient removal rates given the targeted crop yield. These are: 75 lb./ac. N and 37lb./ac. P2O5 for the black soil zone, 68 lb./ac. N and 34 lb./ac. P2O5 for the dark brown soil zone and 55 lb./ac. N and 27 lb./ac. P2O5 for the brown soil zone. Producers are encouraged to use their own rates based on soil tests. Crop Rotation: Diverse crop rotations are recommended to help reduce disease pressure and suppress weeds to manage herbicide resistance. Winter wheat is a very competitive crop that will suppress growth of spring germinating weeds. Crop Protection Insect control: Wheat midge, cutworms, aphids, thrips, mites, grasshoppers, armyworms, slugs and wireworms might require control. Seed treatments are available for wireworm control. Disease control: Fungicide applications in winter wheat typically target leaf diseases. This estimation includes the cost of a single fungicide application for leaf diseases in the black and dark brown soil zones. Fungicide applications should be made based on field history and disease risk during the growing season. Winter wheat can be affected by both leaf diseases and fusarium head blight (FHB). However, winter wheat crops typically pass the susceptible growth stage when conditions favor FHB development. Weed control: Winter wheat is prone to infestation with winter annual weeds, particularly downy and Japanese brome. Herbicide choices were made with this weed in mind, but should be adjusted on individual farms based on the weeds present. Herbicide costs are based on the following herbicide timings. Please refer to general assumptions for details. Please insert herbicide application window.
B4: My Farm | D4: 80th percentile | I4: Average Yield
A5: Soil Zone | C5: Brown | D5: Dark Brown | E5: Black | I5: Brown | J5: Dark Brown | K5: Black
A6: REVENUE PER ACRE
A7: Estimated Yield (bu./ac) (A) | C7: 48.533104 | D7: 60.000747 | E7: 65.881992 | I7: 30.280638 | J7: 45.067739 | K7: 52.414923
A8: Est. On Farm Market Price $/bu. (B) | C8: 6.25 | D8: 6.25 | E8: 6.25 | I8: =C8 | J8: =D8 | K8: =E8
A9: Estimated Gross Revenue/ac (AxB)=C | B9: =ROUND((B8*B7),2) | C9: =ROUND((C8*C7),2) | D9: =ROUND((D8*D7),2) | E9: =ROUND((E8*E7),2) | I9: =ROUND((I8*I7),2) | J9: =ROUND((J8*J7),2) | K9: =ROUND((K8*K7),2)
A11: EXPENSES PER ACRE
A12: Variable Expenses/acre
A13: Seed | C13: 21.311 | D13: 24.054 | E13: 25.742 | I13: =C13 | J13: =D13 | K13: =E13
A14: -Seed Treatments/Inoculants | C14: 6.5021004 | D14: 7.3390044 | E14: 7.8540223 | I14: =C14 | J14: =D14 | K14: =E14
A15: Fertilizer -Nitrogen (N) | C15: 45.026829 | D15: 55.669534 | E15: 61.400221 | I15: =C15 | J15: =D15 | K15: =E15
A16: -Phosphorous (P2O5) | C16: 25.950271 | D16: 32.678119 | E16: 35.561483 | I16: =C16 | J16: =D16 | K16: =E16
A17: -Sulphur and Other | C17: 0 | D17: 0 | E17: 0 | I17: =C17 | J17: =D17 | K17: =E17
A18: Plant Protection -Herbicides | C18: 55.801517 | D18: 59.784183 | E18: 60.381583 | I18: =C18 | J18: =D18 | K18: =E18
A19: -Insecticides | C19: 22.626525 | D19: 22.626525 | E19: 22.626525 | I19: =C19 | J19: =D19 | K19: =E19
A20: -Fungicides | C20: 0 | D20: 15.99 | E20: 15.99 | I20: =C20 | J20: =D20 | K20: =E20
A21: Machinery Operating -Fuel | C21: 16.061797 | D21: 20.077246 | E21: 25.096558 | I21: =C21 | J21: =D21 | K21: =E21
A22: -Repair | C22: 11.563288 | D22: 13.039497 | E22: 14.757902 | I22: =C22 | J22: =D22 | K22: =E22
A23: Custom Work and Hired Labour | C23: 23.5 | D23: 23.25 | E23: 24.25 | I23: =C23 | J23: =D23 | K23: =E23
A24: Crop Insurance Premium | C24: 11.171413 | D24: 8.9985559 | E24: 10.827397 | I24: =C24 | J24: =D24 | K24: =E24
... A27: Interest on Variable Expenses | C27: 21.973993 | D27: 25.839074 | E27: 27.702274 | I27: =C27 | J27: =D27 | K27: =E27
A28: Total Variable Expenses (D) | B28: =SUM(B13:B27) | C28: =SUM(C13:C27) | D28: =SUM(D13:D27) | E28: =SUM(E13:E27) | I28: =SUM(I13:I27) | J28: =SUM(J13:J27) | K28: =SUM(K13:K27)
A30: Other Expenses/acre
A31: Building Repair | C31: 0.74456846 | D31: 0.97564143 | E31: 1.3350883 | I31: =C31 | J31: =D31 | K31: =E31
A32: Property Taxes | C32: 5.0765336 | D32: 6.6426982 | E32: 10.072059 | I32: =C32 | J32: =D32 | K32: =E32
A33: Business Overhead | C33: 2.6074747 | D33: 3.9864277 | E33: 4.6759042 | I33: =C33 | J33: =D33 | K33: =E33
A34: Machinery Depreciation | C34: 47.587379 | D34: 53.662547 | E34: 60.734445 | I34: =C34 | J34: =D34 | K34: =E34
A35: Building Depreciation | C35: 1.45 | D35: 1.9 | E35: 2.6 | I35: =C35 | J35: =D35 | K35: =E35
A36: Machinery Investment | C36: 30.020076 | D36: 33.852541 | E36: 38.313785 | I36: =C36 | J36: =D36 | K36: =E36
A37: Building Investment | C37: 1.3262667 | D37: 1.7378667 | E37: 2.3781333 | I37: =C37 | J37: =D37 | K37: =E37
A38: Land Investment | C38: 70.104 | D38: 80.6565 | E38: 75.38025 | I38: =C38 | J38: =D38 | K38: =E38
